Workbook

Sheet INSTRUCTION
L3: INSTRUCTIONS ON HOW TO USE:
L4: 1. Click the Coverpage Tab. Encode the needed data in the INFORMATION SECTION. Signatures can be affixed to this sheet.
L9: 2. Click the CO-PO Attainment tab. Map the CO to the appropriate PO to ensure that all PO are delivered throughout the study.
L13: 3. The Database Sheet is where you will encode the students' names and the raw scores of their TLAs and ATs. For lecture exam scores, encode the score in the EXAM Sheet. For Research, Practicum, Laboratory encode the OUTPUT scores on the OUTPUT Sheet. On the encoding of the scores, leave blank if the student did not participate/ submit output for the specific task; encode 0 if the student participated but got a score of 0.
A18: CLO-PLO ATTAINMENT SYSTEM
B23: FOR PROFESSIONAL/GEN ED/RESEARCH/INTERNSHIP/SPECIAL COURSES
L26: 4. Grades are automatically computed in the Grade Computation Sheet. Identify the Grading System to be used in the COVERPAGE Sheet.
L27: 5. CO-PO Attainment will be finally computed upon the completion of the course.
L28: Note: For Gen Ed courses, include the irregular students in the encoding as per their enrolled class schedule. No separate computation is needed.
L30: You may click this link for a video tour and tutorial: | P30: CO-PO System TUTORIAL

Sheet COVERPAGE
R3: Semester & Year: | S3: SECOND SEMESTER SY 2024-2025 | Y3: 80-20
R4: Course Code: | W4: LECTURE | Y4: 60-40 | AA4: 0.6
R5: Course Title: | AA5: 0.65
R6: Course Type: | S6: LECTURE | T6: *CHOOSE COURSE TYPE | X6: 1 | AA6: 0.7
R7: Section: | X7: 2 | AA7: 0.75
R8: No. of Students: | S8: =IF('Database (LECTURE-RES-PRAC)'!B8=0,"",'Database (LECTURE-RES-PRAC)'!B8) -> 8 | T8: *will auto count based on encoded students' names | X8: 3 | AA8: 0.8
R9: GRADING SYSTEM | S9: 60-40 | T9: *Choose base grade
R10: Instructor's Name
R11: Threshold | S11: 0.6 | T11: *Determine threshold
A12: CLO-PLO ATTAINMENT SYSTEM
R13: PREPARED BY:
A14: FOR PROFESSIONAL/GENERAL EDUCATION/RESEARCH/INTERNSHIP/OUTPUT-BASED COURSES | S14: Name of Faculty
R15: CHECKED BY:
S16: Program Head
L17: Target Level Criteria | R17: APPROVED BY:
L18: 1 | M18: Low | N18: <50% | O18: students can attain <50% threshold | S18: Dean of College
L19: 2 | M19: Moderate | N19: 50-60% | O19: students can attain >=50%<threshold
L20: 3 | M20: High | N20: >60% | O20: students can attain >= threshold
N21: editable
A22: *At the beginning of each semester, set the CO-PO mapping and targets according the level of CO-PO correlation identified based on the Syllabus. ENCODE MANUALLY.
A23: CO-PO MAPPING (TARGETS)
A26: CLO-PLO | B26: PLO1 | C26: PLO2 | D26: PLO3 | E26: PLO4 | F26: PLO5 | G26: PLO6 | H26: PLO7 | I26: PLO8 | J26: PLO9 | K26: PLO10 | L26: PLO11 | M26: PLO12 | N26: PLO13 | O26: PLO14 | P26: PLO15 | Q26: PLO16
A27: CLO1 | B27: 3 | E27: 3 | J27: 3 | K27: 3
A28: CLO2 | B28: 3 | C28: 3 | E28: 3 | F28: 3 | G28: 3 | H28: 3 | I28: 3 | J28: 3 | K28: 3
A29: CLO3 | B29: 3 | C29: 3 | D29: 3 | E29: 3 | F29: 3 | G29: 3 | H29: 3 | I29: 3 | J29: 3 | K29: 3
A30: CLO4 | B30: 3
A31: CLO5 | B31: 3
A32: CLO6
A33: CLO7
A34: CLO8
A35: CLO9
A36: CLO10
A37: AVERAGE | B37: =IFERROR(AVERAGE(B27:B36),"") -> 3 | C37: =IFERROR(AVERAGE(C27:C36),"") -> 3 | D37: =IFERROR(AVERAGE(D27:D36),"") -> 3 | E37: =IFERROR(AVERAGE(E27:E36),"") -> 3 | F37: =IFERROR(AVERAGE(F27:F36),"") -> 3 | G37: =IFERROR(AVERAGE(G27:G36),"") -> 3 | H37: =IFERROR(AVERAGE(H27:H36),"") -> 3 | I37: =IFERROR(AVERAGE(I27:I36),"") -> 3 | ... Q37: =IFERROR(AVERAGE(Q27:Q36),"")

Sheet Database (LECTURE-RES-PRAC)
A1: CLO-PLO ATTAINMENT SYSTEM
AK2: TLA | CW2: CLO Met Criteria
A3: Semester & Year: | B3: =IF(COVERPAGE!S3=0,"",COVERPAGE!S3) -> SECOND SEMESTER SY 2024-2025 | AK3: AT
A4: Course Code: | B4: CONLAW1 | CW4: If CO Marks (%)>=threshold | CZ4: Y | EA4: CLO1
A5: Course Title: | B5: Constitutional Law I | C5: Distribution of % | D5: TLA | E5: AT | F5: =IF(B6="LECTURE","EXAM",IF(B6="RESEARCH","OUTPUT",IF(B6="PRACTICUM","OUTPUT",IF(B6="STUDENT FORMATION","OUTPUT","")))) -> EXAM | CW5: If CLO Marks (%)<threshold | CZ5: N | EA5: CLO2 | EB5: 0.6
A6: Course Type: | B6: =IF(COVERPAGE!S6="PRACTICUM",COVERPAGE!S6,IF(COVERPAGE!S6="RESEARCH",COVERPAGE!S6,IF(COVERPAGE!S6="LECTURE",COVERPAGE!S6,IF(COVERPAGE!S6="STUDENT FORMATION",COVERPAGE!S6,"")))) -> LECTURE | D6: 0.4 | E6: 0.2 | F6: 0.4 | G6: Please type in your desired weighted distribution here | EA6: CLO3 | EB6: 0.65
A7: Section: | B7: =IF(COVERPAGE!S7=0,"",COVERPAGE!S7) | CW7: Met Level Criteria | EA7: CLO4 | EB7: 0.7
A8: No. of Students: | B8: =COUNTA(B17:B316) -> 8 | CW8: 1 | CX8: Low | CY8: students attained <50% threshold | EA8: CLO5 | EB8: 0.75
A9: Instructor's Name | B9: =IF(COVERPAGE!S10=0,"",COVERPAGE!S10) | CW9: 2 | CX9: Moderate | CY9: students attained >=50%<threshold | EA9: CLO6 | EB9: 0.8
A10: Threshold: | B10: =COVERPAGE!S11 -> 0.6 | CW10: 3 | CX10: High | CY10: students attained >= threshold | EA10: CLO7
C11: GRADING PERIOD | D11: PRELIM | AJ11: MIDTERM | BP11: FINAL | EA11: CLO8
A12: STUDENT ID | B12: STUDENT NAME | C12: ASSESSMENT TYPE | D12: TLA | E12: TLA | F12: TLA | G12: TLA | H12: TLA | I12: AT | J12: AT | AH12: TOTAL | AI12: TOTAL | AJ12: TLA | AK12: TLA | AL12: TLA | AM12: TLA | AN12: TLA | AO12: TLA | AP12: TLA | AQ12: TLA | AR12: TLA | AS12: AT | AT12: AT | AU12: AT | AV12: AT | BN12: TOTAL | BO12: TOTAL | BP12: TLA | BQ12: TLA | BR12: TLA | BS12: TLA | BT12: TLA | BU12: TLA | BV12: AT | BW12: AT | BX12: AT | BY12: AT | BZ12: AT | CT12: TOTAL | CU12: TOTAL | CV12: CLO Attainments (TLA & AT) | EA12: CLO9
C13: ASSESSMENT NO. | D13: 1 | E13: 2 | F13: 3 | G13: 4 | H13: 5 | I13: 1 | J13: 2 | AH13: TLA | AI13: AT | AJ13: 1 | AK13: 2 | AL13: 3 | AM13: 4 | AN13: 5 | AO13: 6 | AP13: 7 | AQ13: 8 | AR13: 10 | AS13: 11 | AT13: 12 | AU13: 13 | AV13: 14 | BN13: TLA | BO13: AT | BP13: 1 | BQ13: 2 | BR13: 3 | BS13: 4 | BT13: 5 | BU13: 6 | BV13: 7 | BW13: 8 | BX13: 9 | BY13: 10 | BZ13: 11 | CT13: TLA | CU13: AT | CV13: CLO1 Marks (%) | CW13: CLO1 Met (Y/N) | CX13: CLO LEVEL | CY13: CLO2 Marks (%) | CZ13: CLO2 Met (Y/N) | DA13: CLO LEVEL | DB13: CLO3 Marks (%) | DC13: CLO3 Met (Y/N) | DD13: CLO LEVEL | DE13: CLO4 Marks (%) | DF13: CLO4 Met (Y/N) | DG13: CLO LEVEL | DH13: CLO5 Marks (%) | DI13: CLO5 Met (Y/N) | DJ13: CLO LEVEL | DK13: CLO6 Marks (%) | DL13: CLO6 Met (Y/N) | DM13: CLO LEVEL | DN13: CLO7 Marks (%) | DO13: CLO7 Met (Y/N) | DP13: CLO LEVEL | DQ13: CLO8 Marks (%) | DR13: CLO8 Met (Y/N) | DS13: CLO LEVEL | DT13: CLO9 Marks (%) | DU13: CLO9 Met (Y/N) | DV13: CLO LEVEL | DW13: CLO10 Marks (%) | DX13: CLO10 Met (Y/N) | DY13: CLO LEVEL | EA13: CLO10
C14: CLO | D14: CLO1 | E14: CLO1 | F14: CLO1 | H14: CLO3 | I14: CLO4 | J14: CLO5 | AJ14: CLO2 | AK14: CLO2 | AL14: CLO2 | AM14: CLO2 | AN14: CLO2 | AO14: CLO2 | AP14: CLO2 | AQ14: CLO2 | AT14: CLO2 | AU14: CLO2 | AV14: CLO2 | BP14: CLO3 | BQ14: CLO3 | BR14: CLO3 | BS14: CLO3 | BT14: CLO3 | BU14: CLO3 | BV14: CLO3 | BW14: CLO3 | BX14: CLO3 | BY14: CLO4 | BZ14: CLO5
C15: DATE/ACTIVITY NAME | D15: Quiz 1 | E15: Written Recitation | F15: Quiz 2 | J15: Portfolio | AJ15: M2 QUIZ 1 | AK15: M2 QUIZ 2 | AL15: M2 QUIZ 3 | AM15: M2 QUIZ 4 | AN15: M2 QUIZ 5 | AO15: M2 QUIZ 6 | AP15: M2 QUIZ 10 | AQ15: M2 QUIZ 11 | BP15: M3 Q1 | BQ15: M3 Q2 | BR15: M3 Q3 | BS15: M3 Q4 | BT15: M3 Q5
C16: COURSE&YR. ⬇️ MAX MARK ➡️ | D16: 20 | E16: 20 | F16: 10 | G16: 20 | H16: 5 | I16: 100 | J16: 100 | AH16: =IF(COUNTA(D16:AG16)>0, SUMIF(D$12:AG$12,"TLA",D16:AG16), "") -> 75 | AI16: =IF(COUNTA(D16:AG16)>0, SUMIF(D$12:AG$12,"AT",D16:AG16), "") -> 200 | AJ16: 10 | AK16: 10 | AL16: 10 | AM16: 10 | AN16: 10 | AO16: 10 | AP16: 10 | AQ16: 10 | AR16: 5 | AS16: 50 | AT16: 25 | AU16: 25 | AV16: 50 | BN16: =IF(COUNTA(AJ16:BM16)>0, SUMIF(AJ$12:BM$12,"TLA",AJ16:BM16), "") -> 85 | BO16: =IF(COUNTA(AJ16:BM16)>0, SUMIF(AJ$12:BM$12,"AT",AJ16:BM16), "") -> 150 | BP16: 10 | BQ16: 10 | BR16: 10 | BS16: 10 | BT16: 10 | BU16: 30 | BV16: 25 | BW16: 25 | BX16: 25 | BY16: 50 | BZ16: 25 | CT16: =IF(COUNTA(BP16:CS16)>0, SUMIF(BP$12:CS$12,"TLA",BP16:CS16), "") -> 80 | CU16: =IF(COUNTA(BP16:CS16)>0, SUMIF(BP$12:CS$12,"AT",BP16:CS16), "") -> 150
B17: trinidad, isabel | C17: bsmt | D17: 17 | E17: 19 | F17: 8 | G17: 20 | H17: 4 | I17: 87 | J17: 78 | AH17: =IF(B17<>"",SUMIF(D$12:AG$12,"TLA",D17:AG17),"") -> 68 | AI17: =IF(B17<>"",SUMIF(D$12:AG$12,"AT",D17:AG17),"") -> 165 | AJ17: 9 | AL17: 9 | AM17: 8 | AN17: 9 | AP17: 10 | AQ17: 8 | AR17: 1 | AS17: 0 | AT17: 24 | AU17: 20 | AV17: 49 | BN17: =IF(B17<>"", SUMIF(AJ$12:BM$12,"TLA",AJ17:BM17), "") -> 54 | BO17: =IF(B17<>"", SUMIF(AJ$12:BM$12,"AT",AJ17:BM17), "") -> 93 | BP17: 8 | BQ17: 9 | BR17: 8 | BS17: 8 | BT17: 8 | BU17: 25 | BV17: 24 | BW17: 23 | BX17: 23 | BY17: 40 | BZ17: 19 | CT17: =IF(B17<>"",SUMIF(BP$12:CS$12,"TLA",BP17:CS17), "") -> 66 | CU17: =IF(B17<>"",SUMIF(BP$12:CS$12,"AT",BP17:CS17), "") -> 129 | CV17: =IF(B17<>"",IFERROR(SUMIF(D$14:CS$14, "CLO1", D17:CS17)/'Grade computation'!I$4,""),"") -> 0.88 | CW17: =IF(CV17="","",IF(CV17>=B$10,"Y","N")) -> Y | CX17: =IF(CV17="","",IF(CV17<50%,1,IF(AND(CV17>=50%,CV17<B$10),2,IF(CV17>=B$10,3)))) -> 3 | CY17: =IF(B17<>"",IFERROR(IF((SUMIF(D$14:CS$14,"CLO2",D17:CS17)/'Grade computation'!I$5)=0,0,(SUMIF(D$14:CS$14,"CLO2",D17:CS17)/'Grade computation'!I$5)),""),"") -> 0.81111111 | CZ17: =IF(CY17="","",IF(CY17>=B$10,"Y","N")) -> Y | DA17: =IF(CY17="","",IF(CY17<50%,1,IF(AND(CY17>=50%,CY17<B$10),2,IF(CY17>=B$10,3)))) -> 3 | DB17: =IF(B17<>"",IFERROR(IF((SUMIF(D$14:CS$14,"CLO3",D17:CS17)/'Grade computation'!I$6)=0,0,(SUMIF(D$14:CS$14,"CLO3",D17:CS17)/'Grade computation'!I$6)),""),"") -> 0.875 | DC17: =IF(DB17="","",IF(DB17>=B$10,"Y","N")) -> Y | DD17: =IF(DB17="","",IF(DB17<50%,1,IF(AND(DB17>=50%,DB17<B$10),2,IF(DB17>=B$10,3)))) -> 3 | DE17: =IF(B17<>"",IFERROR(SUMIF(D$14:CS$14,"CLO4",D17:CS17)/'Grade computation'!I$7,""),"") -> 0.84666667 | DF17: =IF(DE17="","",IF(DE17>=B$10,"Y","N")) -> Y | DG17: =IF(DE17="","",IF(DE17<50%,1,IF(AND(DE17>=50%,DE17<B$10),2,IF(DE17>=B$10,3)))) -> 3 | DH17: =IF(B17<>"",IFERROR(IF((SUMIF(D$14:CS$14,"CLO5",D17:CS17)/'Grade computation'!I$8)=0,0,(SUMIF(D$14:CS$14,"CLO5",D17:CS17)/'Grade computation'!I$8)),""),"") -> 0.776 | DI17: =IF(DH17="","",IF(DH17>=B$10,"Y","N")) -> Y | DJ17: =IF(DH17="","",IF(DH17<50%,1,IF(AND(DH17>=50%,DH17<B$10),2,IF(DH17>=B$10,3)))) -> 3 | DK17: =IF(B17<>"",IFERROR(IF((SUMIF(D$14:CS$14,"CLO6",D17:CS17)/'Grade computation'!I$9)=0,0,(SUMIF(D$14:CS$14,"CLO6",D17:CS17)/'Grade computation'!I$9)),""),"") | DL17: =IF(DK17="","",IF(DK17>=B$10,"Y","N")) | DM17: =IF(DK17="","",IF(DK17<50%,1,IF(AND(DK17>=50%,DK17<B$10),2,IF(DK17>=B$10,3)))) | DN17: =IF(B17<>"",IFERROR(IF((SUMIF(D$14:CS$14,"CLO7",D17:CS17)/'Grade computation'!I$10)=0,0,(SUMIF(D$14:CS$14,"CLO7",D17:CS17)/'Grade computation'!I$10)),""),"") | DO17: =IF(DN17="","",IF(DN17>=B$10,"Y","N")) | DP17: =IF(DN17="","",IF(DN17<50%,1,IF(AND(DN17>=50%,DN17<B$10),2,IF(DN17>=B$10,3)))) | DQ17: =IF(B17<>"",IFERROR(IF((SUMIF(D$14:CS$14,"CLO8",D17:CS17)/'Grade computation'!I$11)=0,0,(SUMIF(D$14:CS$14,"CLO8",D17:CS17)/'Grade computation'!I$11)),""),"") | DR17: =IF(DQ17="","",IF(DQ17>=B$10,"Y","N")) | DS17: =IF(DQ17="","",IF(DQ17<50%,1,IF(AND(DQ17>=50%,DQ17<B$10),2,IF(DQ17>=B$10,3)))) | DT17: =IF(B17<>"",IFERROR(IF((SUMIF(D$14:CS$14,"CLO9",D17:CS17)/'Grade computation'!I$12)=0,0,(SUMIF(D$14:CS$14,"CLO9",D17:CS17)/'Grade computation'!I$12)),""),"") | DU17: =IF(DT17="","",IF(DT17>=B$10,"Y","N")) | DV17: =IF(DT17="","",IF(DT17<50%,1,IF(AND(DT17>=50%,DT17<B$10),2,IF(DT17>=B$10,3)))) | DW17: =IF(B17<>"",IFERROR(IF((SUMIF(D$14:CS$14,"CLO10",D17:CS17)/'Grade computation'!I$13)=0,0,(SUMIF(D$14:CS$14,"CLO10",D17:CS17)/'Grade computation'!I$13)),""),"") | DX17: =IF(DW17="","",IF(DW17>=B$10,"Y","N")) | DY17: =IF(DW17="","",IF(DW17<50%,1,IF(AND(DW17>=50%,DW17<B$10),2,IF(DW17>=B$10,3))))
B18: guevarra, marco | D18: 19 | E18: 15 | F18: 9 | G18: 20 | H18: 5 | I18: 77 | J18: 80 | AH18: =IF(B18<>"",SUMIF(D$12:AG$12,"TLA",D18:AG18),"") -> 68 | AI18: =IF(B18<>"",SUMIF(D$12:AG$12,"AT",D18:AG18),"") -> 157 | AJ18: 6 | AK18: 9 | AL18: 9 | AM18: 9 | AN18: 8 | AO18: 9 | AP18: 8 | AQ18: 10 | AR18: 5 | AS18: 50 | AT18: 22 | AU18: 23 | AV18: 42 | BN18: =IF(B18<>"", SUMIF(AJ$12:BM$12,"TLA",AJ18:BM18), "") -> 73 | BO18: =IF(B18<>"", SUMIF(AJ$12:BM$12,"AT",AJ18:BM18), "") -> 137 | BP18: 8 | BQ18: 9 | BR18: 9 | BS18: 10 | BT18: 8 | BU18: 29 | BV18: 23 | BW18: 20 | BX18: 24 | BY18: 31 | BZ18: 20 | CT18: =IF(B18<>"",SUMIF(BP$12:CS$12,"TLA",BP18:CS18), "") -> 73 | CU18: =IF(B18<>"",SUMIF(BP$12:CS$12,"AT",BP18:CS18), "") -> 118 | CV18: =IF(B18<>"",IFERROR(SUMIF(D$14:CS$14, "CLO1", D18:CS18)/'Grade computation'!I$4,""),"") -> 0.86 | CW18: =IF(CV18="","",IF(CV18>=B$10,"Y","N")) -> Y | CX18: =IF(CV18="","",IF(CV18<50%,1,IF(AND(CV18>=50%,CV18<B$10),2,IF(CV18>=B$10,3)))) -> 3 | CY18: =IF(B18<>"",IFERROR(IF((SUMIF(D$14:CS$14,"CLO2",D18:CS18)/'Grade computation'!I$5)=0,0,(SUMIF(D$14:CS$14,"CLO2",D18:CS18)/'Grade computation'!I$5)),""),"") -> 0.86111111 | CZ18: =IF(CY18="","",IF(CY18>=B$10,"Y","N")) -> Y | DA18: =IF(CY18="","",IF(CY18<50%,1,IF(AND(CY18>=50%,CY18<B$10),2,IF(CY18>=B$10,3)))) -> 3 | DB18: =IF(B18<>"",IFERROR(IF((SUMIF(D$14:CS$14,"CLO3",D18:CS18)/'Grade computation'!I$6)=0,0,(SUMIF(D$14:CS$14,"CLO3",D18:CS18)/'Grade computation'!I$6)),""),"") -> 0.90625 | DC18: =IF(DB18="","",IF(DB18>=B$10,"Y","N")) -> Y | DD18: =IF(DB18="","",IF(DB18<50%,1,IF(AND(DB18>=50%,DB18<B$10),2,IF(DB18>=B$10,3)))) -> 3 | DE18: =IF(B18<>"",IFERROR(SUMIF(D$14:CS$14,"CLO4",D18:CS18)/'Grade computation'!I$7,""),"") -> 0.72 | DF18: =IF(DE18="","",IF(DE18>=B$10,"Y","N")) -> Y | DG18: =IF(DE18="","",IF(DE18<50%,1,IF(AND(DE18>=50%,DE18<B$10),2,IF(DE18>=B$10,3)))) -> 3 | DH18: =IF(B18<>"",IFERROR(IF((SUMIF(D$14:CS$14,"CLO5",D18:CS18)/'Grade computation'!I$8)=0,0,(SUMIF(D$14:CS$14,"CLO5",D18:CS18)/'Grade computation'!I$8)),""),"") -> 0.8 | DI18: =IF(DH18="","",IF(DH18>=B$10,"Y","N")) -> Y | DJ18: =IF(DH18="","",IF(DH18<50%,1,IF(AND(DH18>=50%,DH18<B$10),2,IF(DH18>=B$10,3)))) -> 3 | DK18: =IF(B18<>"",IFERROR(IF((SUMIF(D$14:CS$14,"CLO6",D18:CS18)/'Grade computation'!I$9)=0,0,(SUMIF(D$14:CS$14,"CLO6",D18:CS18)/'Grade computation'!I$9)),""),"") | DL18: =IF(DK18="","",IF(DK18>=B$10,"Y","N")) | DM18: =IF(DK18="","",IF(DK18<50%,1,IF(AND(DK18>=50%,DK18<B$10),2,IF(DK18>=B$10,3)))) | DN18: =IF(B18<>"",IFERROR(IF((SUMIF(D$14:CS$14,"CLO7",D18:CS18)/'Grade computation'!I$10)=0,0,(SUMIF(D$14:CS$14,"CLO7",D18:CS18)/'Grade computation'!I$10)),""),"") | DO18: =IF(DN18="","",IF(DN18>=B$10,"Y","N")) | DP18: =IF(DN18="","",IF(DN18<50%,1,IF(AND(DN18>=50%,DN18<B$10),2,IF(DN18>=B$10,3)))) | DQ18: =IF(B18<>"",IFERROR(IF((SUMIF(D$14:CS$14,"CLO8",D18:CS18)/'Grade computation'!I$11)=0,0,(SUMIF(D$14:CS$14,"CLO8",D18:CS18)/'Grade computation'!I$11)),""),"") | DR18: =IF(DQ18="","",IF(DQ18>=B$10,"Y","N")) | DS18: =IF(DQ18="","",IF(DQ18<50%,1,IF(AND(DQ18>=50%,DQ18<B$10),2,IF(DQ18>=B$10,3)))) | DT18: =IF(B18<>"",IFERROR(IF((SUMIF(D$14:CS$14,"CLO9",D18:CS18)/'Grade computation'!I$12)=0,0,(SUMIF(D$14:CS$14,"CLO9",D18:CS18)/'Grade computation'!I$12)),""),"") | DU18: =IF(DT18="","",IF(DT18>=B$10,"Y","N")) | DV18: =IF(DT18="","",IF(DT18<50%,1,IF(AND(DT18>=50%,DT18<B$10),2,IF(DT18>=B$10,3)))) | DW18: =IF(B18<>"",IFERROR(IF((SUMIF(D$14:CS$14,"CLO10",D18:CS18)/'Grade computation'!I$13)=0,0,(SUMIF(D$14:CS$14,"CLO10",D18:CS18)/'Grade computation'!I$13)),""),"") | DX18: =IF(DW18="","",IF(DW18>=B$10,"Y","N")) | DY18: =IF(DW18="","",IF(DW18<50%,1,IF(AND(DW18>=50%,DW18<B$10),2,IF(DW18>=B$10,3))))
B19: lim, patricia | D19: 19 | E19: 18 | F19: 8 | G19: 20 | H19: 4 | I19: 83 | J19: 79 | AH19: =IF(B19<>"",SUMIF(D$12:AG$12,"TLA",D19:AG19),"") -> 69 | AI19: =IF(B19<>"",SUMIF(D$12:AG$12,"AT",D19:AG19),"") -> 162 | AJ19: 8 | AK19: 9 | AL19: 9 | AM19: 10 | AN19: 10 | AO19: 8 | AP19: 9 | AR19: 3 | AS19: 50 | AT19: 18 | AU19: 23 | AV19: 43 | BN19: =IF(B19<>"", SUMIF(AJ$12:BM$12,"TLA",AJ19:BM19), "") -> 66 | BO19: =IF(B19<>"", SUMIF(AJ$12:BM$12,"AT",AJ19:BM19), "") -> 134 | BP19: 8 | BQ19: 9 | BS19: 9 | BT19: 8 | BU19: 23 | BV19: 22 | BW19: 24 | BX19: 23 | BY19: 39 | BZ19: 24 | CT19: =IF(B19<>"",SUMIF(BP$12:CS$12,"TLA",BP19:CS19), "") -> 57 | CU19: =IF(B19<>"",SUMIF(BP$12:CS$12,"AT",BP19:CS19), "") -> 132 | CV19: =IF(B19<>"",IFERROR(SUMIF(D$14:CS$14, "CLO1", D19:CS19)/'Grade computation'!I$4,""),"") -> 0.9 | CW19: =IF(CV19="","",IF(CV19>=B$10,"Y","N")) -> Y | CX19: =IF(CV19="","",IF(CV19<50%,1,IF(AND(CV19>=50%,CV19<B$10),2,IF(CV19>=B$10,3)))) -> 3 | CY19: =IF(B19<>"",IFERROR(IF((SUMIF(D$14:CS$14,"CLO2",D19:CS19)/'Grade computation'!I$5)=0,0,(SUMIF(D$14:CS$14,"CLO2",D19:CS19)/'Grade computation'!I$5)),""),"") -> 0.81666667 | CZ19: =IF(CY19="","",IF(CY19>=B$10,"Y","N")) -> Y | DA19: =IF(CY19="","",IF(CY19<50%,1,IF(AND(CY19>=50%,CY19<B$10),2,IF(CY19>=B$10,3)))) -> 3 | DB19: =IF(B19<>"",IFERROR(IF((SUMIF(D$14:CS$14,"CLO3",D19:CS19)/'Grade computation'!I$6)=0,0,(SUMIF(D$14:CS$14,"CLO3",D19:CS19)/'Grade computation'!I$6)),""),"") -> 0.8125 | DC19: =IF(DB19="","",IF(DB19>=B$10,"Y","N")) -> Y | DD19: =IF(DB19="","",IF(DB19<50%,1,IF(AND(DB19>=50%,DB19<B$10),2,IF(DB19>=B$10,3)))) -> 3 | DE19: =IF(B19<>"",IFERROR(SUMIF(D$14:CS$14,"CLO4",D19:CS19)/'Grade computation'!I$7,""),"") -> 0.81333333 | DF19: =IF(DE19="","",IF(DE19>=B$10,"Y","N")) -> Y | DG19: =IF(DE19="","",IF(DE19<50%,1,IF(AND(DE19>=50%,DE19<B$10),2,IF(DE19>=B$10,3)))) -> 3 | DH19: =IF(B19<>"",IFERROR(IF((SUMIF(D$14:CS$14,"CLO5",D19:CS19)/'Grade computation'!I$8)=0,0,(SUMIF(D$14:CS$14,"CLO5",D19:CS19)/'Grade computation'!I$8)),""),"") -> 0.824 | DI19: =IF(DH19="","",IF(DH19>=B$10,"Y","N")) -> Y | DJ19: =IF(DH19="","",IF(DH19<50%,1,IF(AND(DH19>=50%,DH19<B$10),2,IF(DH19>=B$10,3)))) -> 3 | DK19: =IF(B19<>"",IFERROR(IF((SUMIF(D$14:CS$14,"CLO6",D19:CS19)/'Grade computation'!I$9)=0,0,(SUMIF(D$14:CS$14,"CLO6",D19:CS19)/'Grade computation'!I$9)),""),"") | DL19: =IF(DK19="","",IF(DK19>=B$10,"Y","N")) | DM19: =IF(DK19="","",IF(DK19<50%,1,IF(AND(DK19>=50%,DK19<B$10),2,IF(DK19>=B$10,3)))) | DN19: =IF(B19<>"",IFERROR(IF((SUMIF(D$14:CS$14,"CLO7",D19:CS19)/'Grade computation'!I$10)=0,0,(SUMIF(D$14:CS$14,"CLO7",D19:CS19)/'Grade computation'!I$10)),""),"") | DO19: =IF(DN19="","",IF(DN19>=B$10,"Y","N")) | DP19: =IF(DN19="","",IF(DN19<50%,1,IF(AND(DN19>=50%,DN19<B$10),2,IF(DN19>=B$10,3)))) | DQ19: =IF(B19<>"",IFERROR(IF((SUMIF(D$14:CS$14,"CLO8",D19:CS19)/'Grade computation'!I$11)=0,0,(SUMIF(D$14:CS$14,"CLO8",D19:CS19)/'Grade computation'!I$11)),""),"") | DR19: =IF(DQ19="","",IF(DQ19>=B$10,"Y","N")) | DS19: =IF(DQ19="","",IF(DQ19<50%,1,IF(AND(DQ19>=50%,DQ19<B$10),2,IF(DQ19>=B$10,3)))) | DT19: =IF(B19<>"",IFERROR(IF((SUMIF(D$14:CS$14,"CLO9",D19:CS19)/'Grade computation'!I$12)=0,0,(SUMIF(D$14:CS$14,"CLO9",D19:CS19)/'Grade computation'!I$12)),""),"") | DU19: =IF(DT19="","",IF(DT19>=B$10,"Y","N")) | DV19: =IF(DT19="","",IF(DT19<50%,1,IF(AND(DT19>=50%,DT19<B$10),2,IF(DT19>=B$10,3)))) | DW19: =IF(B19<>"",IFERROR(IF((SUMIF(D$14:CS$14,"CLO10",D19:CS19)/'Grade computation'!I$13)=0,0,(SUMIF(D$14:CS$14,"CLO10",D19:CS19)/'Grade computation'!I$13)),""),"") | DX19: =IF(DW19="","",IF(DW19>=B$10,"Y","N")) | DY19: =IF(DW19="","",IF(DW19<50%,1,IF(AND(DW19>=50%,DW19<B$10),2,IF(DW19>=B$10,3))))
B20: yap, gerald | E20: 15 | F20: 9 | H20: 4 | I20: 77 | J20: 91 | AH20: =IF(B20<>"",SUMIF(D$12:AG$12,"TLA",D20:AG20),"") -> 28 | AI20: =IF(B20<>"",SUMIF(D$12:AG$12,"AT",D20:AG20),"") -> 168 | AJ20: 8 | AK20: 9 | AM20: 8 | AN20: 8 | AO20: 8 | AP20: 9 | AQ20: 10 | AT20: 20 | AU20: 22 | AV20: 44 | BN20: =IF(B20<>"", SUMIF(AJ$12:BM$12,"TLA",AJ20:BM20), "") -> 60 | BO20: =IF(B20<>"", SUMIF(AJ$12:BM$12,"AT",AJ20:BM20), "") -> 86 | BP20: 8 | BQ20: 8 | BR20: 9 | BS20: 9 | BT20: 7 | BV20: 20 | BW20: 21 | BX20: 21 | BY20: 48 | BZ20: 21 | CT20: =IF(B20<>"",SUMIF(BP$12:CS$12,"TLA",BP20:CS20), "") -> 41 | CU20: =IF(B20<>"",SUMIF(BP$12:CS$12,"AT",BP20:CS20), "") -> 131 | CV20: =IF(B20<>"",IFERROR(SUMIF(D$14:CS$14, "CLO1", D20:CS20)/'Grade computation'!I$4,""),"") -> 0.48 | CW20: =IF(CV20="","",IF(CV20>=B$10,"Y","N")) -> N | CX20: =IF(CV20="","",IF(CV20<50%,1,IF(AND(CV20>=50%,CV20<B$10),2,IF(CV20>=B$10,3)))) -> 1 | CY20: =IF(B20<>"",IFERROR(IF((SUMIF(D$14:CS$14,"CLO2",D20:CS20)/'Grade computation'!I$5)=0,0,(SUMIF(D$14:CS$14,"CLO2",D20:CS20)/'Grade computation'!I$5)),""),"") -> 0.81111111 | CZ20: =IF(CY20="","",IF(CY20>=B$10,"Y","N")) -> Y | DA20: =IF(CY20="","",IF(CY20<50%,1,IF(AND(CY20>=50%,CY20<B$10),2,IF(CY20>=B$10,3)))) -> 3 | DB20: =IF(B20<>"",IFERROR(IF((SUMIF(D$14:CS$14,"CLO3",D20:CS20)/'Grade computation'!I$6)=0,0,(SUMIF(D$14:CS$14,"CLO3",D20:CS20)/'Grade computation'!I$6)),""),"") -> 0.66875 | DC20: =IF(DB20="","",IF(DB20>=B$10,"Y","N")) -> Y | DD20: =IF(DB20="","",IF(DB20<50%,1,IF(AND(DB20>=50%,DB20<B$10),2,IF(DB20>=B$10,3)))) -> 3 | DE20: =IF(B20<>"",IFERROR(SUMIF(D$14:CS$14,"CLO4",D20:CS20)/'Grade computation'!I$7,""),"") -> 0.83333333 | DF20: =IF(DE20="","",IF(DE20>=B$10,"Y","N")) -> Y | DG20: =IF(DE20="","",IF(DE20<50%,1,IF(AND(DE20>=50%,DE20<B$10),2,IF(DE20>=B$10,3)))) -> 3 | DH20: =IF(B20<>"",IFERROR(IF((SUMIF(D$14:CS$14,"CLO5",D20:CS20)/'Grade computation'!I$8)=0,0,(SUMIF(D$14:CS$14,"CLO5",D20:CS20)/'Grade computation'!I$8)),""),"") -> 0.896 | DI20: =IF(DH20="","",IF(DH20>=B$10,"Y","N")) -> Y | DJ20: =IF(DH20="","",IF(DH20<50%,1,IF(AND(DH20>=50%,DH20<B$10),2,IF(DH20>=B$10,3)))) -> 3 | DK20: =IF(B20<>"",IFERROR(IF((SUMIF(D$14:CS$14,"CLO6",D20:CS20)/'Grade computation'!I$9)=0,0,(SUMIF(D$14:CS$14,"CLO6",D20:CS20)/'Grade computation'!I$9)),""),"") | DL20: =IF(DK20="","",IF(DK20>=B$10,"Y","N")) | DM20: =IF(DK20="","",IF(DK20<50%,1,IF(AND(DK20>=50%,DK20<B$10),2,IF(DK20>=B$10,3)))) | DN20: =IF(B20<>"",IFERROR(IF((SUMIF(D$14:CS$14,"CLO7",D20:CS20)/'Grade computation'!I$10)=0,0,(SUMIF(D$14:CS$14,"CLO7",D20:CS20)/'Grade computation'!I$10)),""),"") | DO20: =IF(DN20="","",IF(DN20>=B$10,"Y","N")) | DP20: =IF(DN20="","",IF(DN20<50%,1,IF(AND(DN20>=50%,DN20<B$10),2,IF(DN20>=B$10,3)))) | DQ20: =IF(B20<>"",IFERROR(IF((SUMIF(D$14:CS$14,"CLO8",D20:CS20)/'Grade computation'!I$11)=0,0,(SUMIF(D$14:CS$14,"CLO8",D20:CS20)/'Grade computation'!I$11)),""),"") | DR20: =IF(DQ20="","",IF(DQ20>=B$10,"Y","N")) | DS20: =IF(DQ20="","",IF(DQ20<50%,1,IF(AND(DQ20>=50%,DQ20<B$10),2,IF(DQ20>=B$10,3)))) | DT20: =IF(B20<>"",IFERROR(IF((SUMIF(D$14:CS$14,"CLO9",D20:CS20)/'Grade computation'!I$12)=0,0,(SUMIF(D$14:CS$14,"CLO9",D20:CS20)/'Grade computation'!I$12)),""),"") | DU20: =IF(DT20="","",IF(DT20>=B$10,"Y","N")) | DV20: =IF(DT20="","",IF(DT20<50%,1,IF(AND(DT20>=50%,DT20<B$10),2,IF(DT20>=B$10,3)))) | DW20: =IF(B20<>"",IFERROR(IF((SUMIF(D$14:CS$14,"CLO10",D20:CS20)/'Grade computation'!I$13)=0,0,(SUMIF(D$14:CS$14,"CLO10",D20:CS20)/'Grade computation'!I$13)),""),"") | DX20: =IF(DW20="","",IF(DW20>=B$10,"Y","N")) | DY20: =IF(DW20="","",IF(DW20<50%,1,IF(AND(DW20>=50%,DW20<B$10),2,IF(DW20>=B$10,3))))
B21: chua, angeline | D21: 18 | E21: 15 | F21: 9 | H21: 4 | I21: 87 | J21: 92 | AH21: =IF(B21<>"",SUMIF(D$12:AG$12,"TLA",D21:AG21),"") -> 46 | AI21: =IF(B21<>"",SUMIF(D$12:AG$12,"AT",D21:AG21),"") -> 179 | AK21: 10 | AL21: 9 | AM21: 10 | AN21: 8 | AP21: 9 | AQ21: 9 | AT21: 24 | AU21: 23 | AV21: 42 | BN21: =IF(B21<>"", SUMIF(AJ$12:BM$12,"TLA",AJ21:BM21), "") -> 55 | BO21: =IF(B21<>"", SUMIF(AJ$12:BM$12,"AT",AJ21:BM21), "") -> 89 | BP21: 8 | BQ21: 9 | BR21: 8 | BS21: 8 | BT21: 8 | BU21: 25 | BV21: 24 | BX21: 21 | BY21: 40 | BZ21: 23 | CT21: =IF(B21<>"",SUMIF(BP$12:CS$12,"TLA",BP21:CS21), "") -> 66 | CU21: =IF(B21<>"",SUMIF(BP$12:CS$12,"AT",BP21:CS21), "") -> 108 | CV21: =IF(B21<>"",IFERROR(SUMIF(D$14:CS$14, "CLO1", D21:CS21)/'Grade computation'!I$4,""),"") -> 0.84 | CW21: =IF(CV21="","",IF(CV21>=B$10,"Y","N")) -> Y | CX21: =IF(CV21="","",IF(CV21<50%,1,IF(AND(CV21>=50%,CV21<B$10),2,IF(CV21>=B$10,3)))) -> 3 | CY21: =IF(B21<>"",IFERROR(IF((SUMIF(D$14:CS$14,"CLO2",D21:CS21)/'Grade computation'!I$5)=0,0,(SUMIF(D$14:CS$14,"CLO2",D21:CS21)/'Grade computation'!I$5)),""),"") -> 0.8 | CZ21: =IF(CY21="","",IF(CY21>=B$10,"Y","N")) -> Y | DA21: =IF(CY21="","",IF(CY21<50%,1,IF(AND(CY21>=50%,CY21<B$10),2,IF(CY21>=B$10,3)))) -> 3 | DB21: =IF(B21<>"",IFERROR(IF((SUMIF(D$14:CS$14,"CLO3",D21:CS21)/'Grade computation'!I$6)=0,0,(SUMIF(D$14:CS$14,"CLO3",D21:CS21)/'Grade computation'!I$6)),""),"") -> 0.71875 | DC21: =IF(DB21="","",IF(DB21>=B$10,"Y","N")) -> Y | DD21: =IF(DB21="","",IF(DB21<50%,1,IF(AND(DB21>=50%,DB21<B$10),2,IF(DB21>=B$10,3)))) -> 3 | DE21: =IF(B21<>"",IFERROR(SUMIF(D$14:CS$14,"CLO4",D21:CS21)/'Grade computation'!I$7,""),"") -> 0.84666667 | DF21: =IF(DE21="","",IF(DE21>=B$10,"Y","N")) -> Y | DG21: =IF(DE21="","",IF(DE21<50%,1,IF(AND(DE21>=50%,DE21<B$10),2,IF(DE21>=B$10,3)))) -> 3 | DH21: =IF(B21<>"",IFERROR(IF((SUMIF(D$14:CS$14,"CLO5",D21:CS21)/'Grade computation'!I$8)=0,0,(SUMIF(D$14:CS$14,"CLO5",D21:CS21)/'Grade computation'!I$8)),""),"") -> 0.92 | DI21: =IF(DH21="","",IF(DH21>=B$10,"Y","N")) -> Y | DJ21: =IF(DH21="","",IF(DH21<50%,1,IF(AND(DH21>=50%,DH21<B$10),2,IF(DH21>=B$10,3)))) -> 3 | DK21: =IF(B21<>"",IFERROR(IF((SUMIF(D$14:CS$14,"CLO6",D21:CS21)/'Grade computation'!I$9)=0,0,(SUMIF(D$14:CS$14,"CLO6",D21:CS21)/'Grade computation'!I$9)),""),"") | DL21: =IF(DK21="","",IF(DK21>=B$10,"Y","N")) | DM21: =IF(DK21="","",IF(DK21<50%,1,IF(AND(DK21>=50%,DK21<B$10),2,IF(DK21>=B$10,3)))) | DN21: =IF(B21<>"",IFERROR(IF((SUMIF(D$14:CS$14,"CLO7",D21:CS21)/'Grade computation'!I$10)=0,0,(SUMIF(D$14:CS$14,"CLO7",D21:CS21)/'Grade computation'!I$10)),""),"") | DO21: =IF(DN21="","",IF(DN21>=B$10,"Y","N")) | DP21: =IF(DN21="","",IF(DN21<50%,1,IF(AND(DN21>=50%,DN21<B$10),2,IF(DN21>=B$10,3)))) | DQ21: =IF(B21<>"",IFERROR(IF((SUMIF(D$14:CS$14,"CLO8",D21:CS21)/'Grade computation'!I$11)=0,0,(SUMIF(D$14:CS$14,"CLO8",D21:CS21)/'Grade computation'!I$11)),""),"") | DR21: =IF(DQ21="","",IF(DQ21>=B$10,"Y","N")) | DS21: =IF(DQ21="","",IF(DQ21<50%,1,IF(AND(DQ21>=50%,DQ21<B$10),2,IF(DQ21>=B$10,3)))) | DT21: =IF(B21<>"",IFERROR(IF((SUMIF(D$14:CS$14,"CLO9",D21:CS21)/'Grade computation'!I$12)=0,0,(SUMIF(D$14:CS$14,"CLO9",D21:CS21)/'Grade computation'!I$12)),""),"") | DU21: =IF(DT21="","",IF(DT21>=B$10,"Y","N")) | DV21: =IF(DT21="","",IF(DT21<50%,1,IF(AND(DT21>=50%,DT21<B$10),2,IF(DT21>=B$10,3)))) | DW21: =IF(B21<>"",IFERROR(IF((SUMIF(D$14:CS$14,"CLO10",D21:CS21)/'Grade computation'!I$13)=0,0,(SUMIF(D$14:CS$14,"CLO10",D21:CS21)/'Grade computation'!I$13)),""),"") | DX21: =IF(DW21="","",IF(DW21>=B$10,"Y","N")) | DY21: =IF(DW21="","",IF(DW21<50%,1,IF(AND(DW21>=50%,DW21<B$10),2,IF(DW21>=B$10,3))))
B22: tan, russell | D22: 18 | E22: 17 | H22: 5 | I22: 90 | J22: 79 | AH22: =IF(B22<>"",SUMIF(D$12:AG$12,"TLA",D22:AG22),"") -> 40 | AI22: =IF(B22<>"",SUMIF(D$12:AG$12,"AT",D22:AG22),"") -> 169 | AJ22: 9 | AM22: 9 | AN22: 9 | AO22: 9 | AQ22: 9 | AT22: 24 | AU22: 20 | AV22: 40 | BN22: =IF(B22<>"", SUMIF(AJ$12:BM$12,"TLA",AJ22:BM22), "") -> 45 | BO22: =IF(B22<>"", SUMIF(AJ$12:BM$12,"AT",AJ22:BM22), "") -> 84 | BP22: 9 | BQ22: 8 | BR22: 10 | BS22: 8 | BT22: 9 | BU22: 19 | BV22: 14 | BW22: 23 | BX22: 24 | BY22: 36 | BZ22: 23 | CT22: =IF(B22<>"",SUMIF(BP$12:CS$12,"TLA",BP22:CS22), "") -> 63 | CU22: =IF(B22<>"",SUMIF(BP$12:CS$12,"AT",BP22:CS22), "") -> 120 | CV22: =IF(B22<>"",IFERROR(SUMIF(D$14:CS$14, "CLO1", D22:CS22)/'Grade computation'!I$4,""),"") -> 0.7 | CW22: =IF(CV22="","",IF(CV22>=B$10,"Y","N")) -> Y | CX22: =IF(CV22="","",IF(CV22<50%,1,IF(AND(CV22>=50%,CV22<B$10),2,IF(CV22>=B$10,3)))) -> 3 | CY22: =IF(B22<>"",IFERROR(IF((SUMIF(D$14:CS$14,"CLO2",D22:CS22)/'Grade computation'!I$5)=0,0,(SUMIF(D$14:CS$14,"CLO2",D22:CS22)/'Grade computation'!I$5)),""),"") -> 0.71666667 | CZ22: =IF(CY22="","",IF(CY22>=B$10,"Y","N")) -> Y | DA22: =IF(CY22="","",IF(CY22<50%,1,IF(AND(CY22>=50%,CY22<B$10),2,IF(CY22>=B$10,3)))) -> 3 | DB22: =IF(B22<>"",IFERROR(IF((SUMIF(D$14:CS$14,"CLO3",D22:CS22)/'Grade computation'!I$6)=0,0,(SUMIF(D$14:CS$14,"CLO3",D22:CS22)/'Grade computation'!I$6)),""),"") -> 0.80625 | DC22: =IF(DB22="","",IF(DB22>=B$10,"Y","N")) -> Y | DD22: =IF(DB22="","",IF(DB22<50%,1,IF(AND(DB22>=50%,DB22<B$10),2,IF(DB22>=B$10,3)))) -> 3 | DE22: =IF(B22<>"",IFERROR(SUMIF(D$14:CS$14,"CLO4",D22:CS22)/'Grade computation'!I$7,""),"") -> 0.84 | DF22: =IF(DE22="","",IF(DE22>=B$10,"Y","N")) -> Y | DG22: =IF(DE22="","",IF(DE22<50%,1,IF(AND(DE22>=50%,DE22<B$10),2,IF(DE22>=B$10,3)))) -> 3 | DH22: =IF(B22<>"",IFERROR(IF((SUMIF(D$14:CS$14,"CLO5",D22:CS22)/'Grade computation'!I$8)=0,0,(SUMIF(D$14:CS$14,"CLO5",D22:CS22)/'Grade computation'!I$8)),""),"") -> 0.816 | DI22: =IF(DH22="","",IF(DH22>=B$10,"Y","N")) -> Y | DJ22: =IF(DH22="","",IF(DH22<50%,1,IF(AND(DH22>=50%,DH22<B$10),2,IF(DH22>=B$10,3)))) -> 3 | DK22: =IF(B22<>"",IFERROR(IF((SUMIF(D$14:CS$14,"CLO6",D22:CS22)/'Grade computation'!I$9)=0,0,(SUMIF(D$14:CS$14,"CLO6",D22:CS22)/'Grade computation'!I$9)),""),"") | DL22: =IF(DK22="","",IF(DK22>=B$10,"Y","N")) | DM22: =IF(DK22="","",IF(DK22<50%,1,IF(AND(DK22>=50%,DK22<B$10),2,IF(DK22>=B$10,3)))) | DN22: =IF(B22<>"",IFERROR(IF((SUMIF(D$14:CS$14,"CLO7",D22:CS22)/'Grade computation'!I$10)=0,0,(SUMIF(D$14:CS$14,"CLO7",D22:CS22)/'Grade computation'!I$10)),""),"") | DO22: =IF(DN22="","",IF(DN22>=B$10,"Y","N")) | DP22: =IF(DN22="","",IF(DN22<50%,1,IF(AND(DN22>=50%,DN22<B$10),2,IF(DN22>=B$10,3)))) | DQ22: =IF(B22<>"",IFERROR(IF((SUMIF(D$14:CS$14,"CLO8",D22:CS22)/'Grade computation'!I$11)=0,0,(SUMIF(D$14:CS$14,"CLO8",D22:CS22)/'Grade computation'!I$11)),""),"") | DR22: =IF(DQ22="","",IF(DQ22>=B$10,"Y","N")) | DS22: =IF(DQ22="","",IF(DQ22<50%,1,IF(AND(DQ22>=50%,DQ22<B$10),2,IF(DQ22>=B$10,3)))) | DT22: =IF(B22<>"",IFERROR(IF((SUMIF(D$14:CS$14,"CLO9",D22:CS22)/'Grade computation'!I$12)=0,0,(SUMIF(D$14:CS$14,"CLO9",D22:CS22)/'Grade computation'!I$12)),""),"") | DU22: =IF(DT22="","",IF(DT22>=B$10,"Y","N")) | DV22: =IF(DT22="","",IF(DT22<50%,1,IF(AND(DT22>=50%,DT22<B$10),2,IF(DT22>=B$10,3)))) | DW22: =IF(B22<>"",IFERROR(IF((SUMIF(D$14:CS$14,"CLO10",D22:CS22)/'Grade computation'!I$13)=0,0,(SUMIF(D$14:CS$14,"CLO10",D22:CS22)/'Grade computation'!I$13)),""),"") | DX22: =IF(DW22="","",IF(DW22>=B$10,"Y","N")) | DY22: =IF(DW22="","",IF(DW22<50%,1,IF(AND(DW22>=50%,DW22<B$10),2,IF(DW22>=B$10,3))))
B23: ong, bernadette | D23: 16 | E23: 17 | F23: 8 | H23: 4 | I23: 97 | J23: 85 | AH23: =IF(B23<>"",SUMIF(D$12:AG$12,"TLA",D23:AG23),"") -> 45 | AI23: =IF(B23<>"",SUMIF(D$12:AG$12,"AT",D23:AG23),"") -> 182 | AJ23: 6 | AK23: 10 | AL23: 8 | AM23: 8 | AN23: 8 | AO23: 10 | AP23: 9 | AQ23: 8 | AT23: 24 | AU23: 15 | AV23: 38 | BN23: =IF(B23<>"", SUMIF(AJ$12:BM$12,"TLA",AJ23:BM23), "") -> 67 | BO23: =IF(B23<>"", SUMIF(AJ$12:BM$12,"AT",AJ23:BM23), "") -> 77 | BP23: 8 | BQ23: 8 | BR23: 8 | BS23: 8 | BT23: 8 | BU23: 25 | BV23: 22 | BW23: 20 | BX23: 22 | BY23: 31 | BZ23: 23 | CT23: =IF(B23<>"",SUMIF(BP$12:CS$12,"TLA",BP23:CS23), "") -> 65 | CU23: =IF(B23<>"",SUMIF(BP$12:CS$12,"AT",BP23:CS23), "") -> 118 | CV23: =IF(B23<>"",IFERROR(SUMIF(D$14:CS$14, "CLO1", D23:CS23)/'Grade computation'!I$4,""),"") -> 0.82 | CW23: =IF(CV23="","",IF(CV23>=B$10,"Y","N")) -> Y | CX23: =IF(CV23="","",IF(CV23<50%,1,IF(AND(CV23>=50%,CV23<B$10),2,IF(CV23>=B$10,3)))) -> 3 | CY23: =IF(B23<>"",IFERROR(IF((SUMIF(D$14:CS$14,"CLO2",D23:CS23)/'Grade computation'!I$5)=0,0,(SUMIF(D$14:CS$14,"CLO2",D23:CS23)/'Grade computation'!I$5)),""),"") -> 0.8 | CZ23: =IF(CY23="","",IF(CY23>=B$10,"Y","N")) -> Y | DA23: =IF(CY23="","",IF(CY23<50%,1,IF(AND(CY23>=50%,CY23<B$10),2,IF(CY23>=B$10,3)))) -> 3 | DB23: =IF(B23<>"",IFERROR(IF((SUMIF(D$14:CS$14,"CLO3",D23:CS23)/'Grade computation'!I$6)=0,0,(SUMIF(D$14:CS$14,"CLO3",D23:CS23)/'Grade computation'!I$6)),""),"") -> 0.83125 | DC23: =IF(DB23="","",IF(DB23>=B$10,"Y","N")) -> Y | DD23: =IF(DB23="","",IF(DB23<50%,1,IF(AND(DB23>=50%,DB23<B$10),2,IF(DB23>=B$10,3)))) -> 3 | DE23: =IF(B23<>"",IFERROR(SUMIF(D$14:CS$14,"CLO4",D23:CS23)/'Grade computation'!I$7,""),"") -> 0.85333333 | DF23: =IF(DE23="","",IF(DE23>=B$10,"Y","N")) -> Y | DG23: =IF(DE23="","",IF(DE23<50%,1,IF(AND(DE23>=50%,DE23<B$10),2,IF(DE23>=B$10,3)))) -> 3 | DH23: =IF(B23<>"",IFERROR(IF((SUMIF(D$14:CS$14,"CLO5",D23:CS23)/'Grade computation'!I$8)=0,0,(SUMIF(D$14:CS$14,"CLO5",D23:CS23)/'Grade computation'!I$8)),""),"") -> 0.864 | DI23: =IF(DH23="","",IF(DH23>=B$10,"Y","N")) -> Y | DJ23: =IF(DH23="","",IF(DH23<50%,1,IF(AND(DH23>=50%,DH23<B$10),2,IF(DH23>=B$10,3)))) -> 3 | DK23: =IF(B23<>"",IFERROR(IF((SUMIF(D$14:CS$14,"CLO6",D23:CS23)/'Grade computation'!I$9)=0,0,(SUMIF(D$14:CS$14,"CLO6",D23:CS23)/'Grade computation'!I$9)),""),"") | DL23: =IF(DK23="","",IF(DK23>=B$10,"Y","N")) | DM23: =IF(DK23="","",IF(DK23<50%,1,IF(AND(DK23>=50%,DK23<B$10),2,IF(DK23>=B$10,3)))) | DN23: =IF(B23<>"",IFERROR(IF((SUMIF(D$14:CS$14,"CLO7",D23:CS23)/'Grade computation'!I$10)=0,0,(SUMIF(D$14:CS$14,"CLO7",D23:CS23)/'Grade computation'!I$10)),""),"") | DO23: =IF(DN23="","",IF(DN23>=B$10,"Y","N")) | DP23: =IF(DN23="","",IF(DN23<50%,1,IF(AND(DN23>=50%,DN23<B$10),2,IF(DN23>=B$10,3)))) | DQ23: =IF(B23<>"",IFERROR(IF((SUMIF(D$14:CS$14,"CLO8",D23:CS23)/'Grade computation'!I$11)=0,0,(SUMIF(D$14:CS$14,"CLO8",D23:CS23)/'Grade computation'!I$11)),""),"") | DR23: =IF(DQ23="","",IF(DQ23>=B$10,"Y","N")) | DS23: =IF(DQ23="","",IF(DQ23<50%,1,IF(AND(DQ23>=50%,DQ23<B$10),2,IF(DQ23>=B$10,3)))) | DT23: =IF(B23<>"",IFERROR(IF((SUMIF(D$14:CS$14,"CLO9",D23:CS23)/'Grade computation'!I$12)=0,0,(SUMIF(D$14:CS$14,"CLO9",D23:CS23)/'Grade computation'!I$12)),""),"") | DU23: =IF(DT23="","",IF(DT23>=B$10,"Y","N")) | DV23: =IF(DT23="","",IF(DT23<50%,1,IF(AND(DT23>=50%,DT23<B$10),2,IF(DT23>=B$10,3)))) | DW23: =IF(B23<>"",IFERROR(IF((SUMIF(D$14:CS$14,"CLO10",D23:CS23)/'Grade computation'!I$13)=0,0,(SUMIF(D$14:CS$14,"CLO10",D23:CS23)/'Grade computation'!I$13)),""),"") | DX23: =IF(DW23="","",IF(DW23>=B$10,"Y","N")) | DY23: =IF(DW23="","",IF(DW23<50%,1,IF(AND(DW23>=50%,DW23<B$10),2,IF(DW23>=B$10,3))))
B24: sy, victor | D24: 16 | E24: 15 | F24: 8 | H24: 3 | J24: 84 | AH24: =IF(B24<>"",SUMIF(D$12:AG$12,"TLA",D24:AG24),"") -> 42 | AI24: =IF(B24<>"",SUMIF(D$12:AG$12,"AT",D24:AG24),"") -> 84 | AJ24: 10 | AK24: 9 | AL24: 8 | AM24: 9 | AN24: 8 | AO24: 9 | AP24: 9 | AQ24: 10 | AT24: 24 | AU24: 24 | AV24: 36 | BN24: =IF(B24<>"", SUMIF(AJ$12:BM$12,"TLA",AJ24:BM24), "") -> 72 | BO24: =IF(B24<>"", SUMIF(AJ$12:BM$12,"AT",AJ24:BM24), "") -> 84 | BP24: 9 | BQ24: 8 | BR24: 8 | BS24: 9 | BT24: 6 | BU24: 28 | BV24: 23 | BW24: 24 | BX24: 24 | CT24: =IF(B24<>"",SUMIF(BP$12:CS$12,"TLA",BP24:CS24), "") -> 68 | CU24: =IF(B24<>"",SUMIF(BP$12:CS$12,"AT",BP24:CS24), "") -> 71 | CV24: =IF(B24<>"",IFERROR(SUMIF(D$14:CS$14, "CLO1", D24:CS24)/'Grade computation'!I$4,""),"") -> 0.78 | CW24: =IF(CV24="","",IF(CV24>=B$10,"Y","N")) -> Y | CX24: =IF(CV24="","",IF(CV24<50%,1,IF(AND(CV24>=50%,CV24<B$10),2,IF(CV24>=B$10,3)))) -> 3 | CY24: =IF(B24<>"",IFERROR(IF((SUMIF(D$14:CS$14,"CLO2",D24:CS24)/'Grade computation'!I$5)=0,0,(SUMIF(D$14:CS$14,"CLO2",D24:CS24)/'Grade computation'!I$5)),""),"") -> 0.86666667 | CZ24: =IF(CY24="","",IF(CY24>=B$10,"Y","N")) -> Y | DA24: =IF(CY24="","",IF(CY24<50%,1,IF(AND(CY24>=50%,CY24<B$10),2,IF(CY24>=B$10,3)))) -> 3 | DB24: =IF(B24<>"",IFERROR(IF((SUMIF(D$14:CS$14,"CLO3",D24:CS24)/'Grade computation'!I$6)=0,0,(SUMIF(D$14:CS$14,"CLO3",D24:CS24)/'Grade computation'!I$6)),""),"") -> 0.8875 | DC24: =IF(DB24="","",IF(DB24>=B$10,"Y","N")) -> Y | DD24: =IF(DB24="","",IF(DB24<50%,1,IF(AND(DB24>=50%,DB24<B$10),2,IF(DB24>=B$10,3)))) -> 3 | DE24: =IF(B24<>"",IFERROR(SUMIF(D$14:CS$14,"CLO4",D24:CS24)/'Grade computation'!I$7,""),"") -> 0 | DF24: =IF(DE24="","",IF(DE24>=B$10,"Y","N")) -> N | DG24: =IF(DE24="","",IF(DE24<50%,1,IF(AND(DE24>=50%,DE24<B$10),2,IF(DE24>=B$10,3)))) -> 1 | DH24: =IF(B24<>"",IFERROR(IF((SUMIF(D$14:CS$14,"CLO5",D24:CS24)/'Grade computation'!I$8)=0,0,(SUMIF(D$14:CS$14,"CLO5",D24:CS24)/'Grade computation'!I$8)),""),"") -> 0.672 | DI24: =IF(DH24="","",IF(DH24>=B$10,"Y","N")) -> Y | DJ24: =IF(DH24="","",IF(DH24<50%,1,IF(AND(DH24>=50%,DH24<B$10),2,IF(DH24>=B$10,3)))) -> 3 | DK24: =IF(B24<>"",IFERROR(IF((SUMIF(D$14:CS$14,"CLO6",D24:CS24)/'Grade computation'!I$9)=0,0,(SUMIF(D$14:CS$14,"CLO6",D24:CS24)/'Grade computation'!I$9)),""),"") | DL24: =IF(DK24="","",IF(DK24>=B$10,"Y","N")) | DM24: =IF(DK24="","",IF(DK24<50%,1,IF(AND(DK24>=50%,DK24<B$10),2,IF(DK24>=B$10,3)))) | DN24: =IF(B24<>"",IFERROR(IF((SUMIF(D$14:CS$14,"CLO7",D24:CS24)/'Grade computation'!I$10)=0,0,(SUMIF(D$14:CS$14,"CLO7",D24:CS24)/'Grade computation'!I$10)),""),"") | DO24: =IF(DN24="","",IF(DN24>=B$10,"Y","N")) | DP24: =IF(DN24="","",IF(DN24<50%,1,IF(AND(DN24>=50%,DN24<B$10),2,IF(DN24>=B$10,3)))) | DQ24: =IF(B24<>"",IFERROR(IF((SUMIF(D$14:CS$14,"CLO8",D24:CS24)/'Grade computation'!I$11)=0,0,(SUMIF(D$14:CS$14,"CLO8",D24:CS24)/'Grade computation'!I$11)),""),"") | DR24: =IF(DQ24="","",IF(DQ24>=B$10,"Y","N")) | DS24: =IF(DQ24="","",IF(DQ24<50%,1,IF(AND(DQ24>=50%,DQ24<B$10),2,IF(DQ24>=B$10,3)))) | DT24: =IF(B24<>"",IFERROR(IF((SUMIF(D$14:CS$14,"CLO9",D24:CS24)/'Grade computation'!I$12)=0,0,(SUMIF(D$14:CS$14,"CLO9",D24:CS24)/'Grade computation'!I$12)),""),"") | DU24: =IF(DT24="","",IF(DT24>=B$10,"Y","N")) | DV24: =IF(DT24="","",IF(DT24<50%,1,IF(AND(DT24>=50%,DT24<B$10),2,IF(DT24>=B$10,3)))) | DW24: =IF(B24<>"",IFERROR(IF((SUMIF(D$14:CS$14,"CLO10",D24:CS24)/'Grade computation'!I$13)=0,0,(SUMIF(D$14:CS$14,"CLO10",D24:CS24)/'Grade computation'!I$13)),""),"") | DX24: =IF(DW24="","",IF(DW24>=B$10,"Y","N")) | DY24: =IF(DW24="","",IF(DW24<50%,1,IF(AND(DW24>=50%,DW24<B$10),2,IF(DW24>=B$10,3))))
AH25: =IF(B25<>"",SUMIF(D$12:AG$12,"TLA",D25:AG25),"") | AI25: =IF(B25<>"",SUMIF(D$12:AG$12,"AT",D25:AG25),"") | BN25: =IF(B25<>"", SUMIF(AJ$12:BM$12,"TLA",AJ25:BM25), "") | BO25: =IF(B25<>"", SUMIF(AJ$12:BM$12,"AT",AJ25:BM25), "") | CT25: =IF(B25<>"",SUMIF(BP$12:CS$12,"TLA",BP25:CS25), "") | CU25: =IF(B25<>"",SUMIF(BP$12:CS$12,"AT",BP25:CS25), "") | CV25: =IF(B25<>"",IFERROR(SUMIF(D$14:CS$14, "CLO1", D25:CS25)/'Grade computation'!I$4,""),"") | CW25: =IF(CV25="","",IF(CV25>=B$10,"Y","N")) | CX25: =IF(CV25="","",IF(CV25<50%,1,IF(AND(CV25>=50%,CV25<B$10),2,IF(CV25>=B$10,3)))) | CY25: =IF(B25<>"",IFERROR(IF((SUMIF(D$14:CS$14,"CLO2",D25:CS25)/'Grade computation'!I$5)=0,0,(SUMIF(D$14:CS$14,"CLO2",D25:CS25)/'Grade computation'!I$5)),""),"") | CZ25: =IF(CY25="","",IF(CY25>=B$10,"Y","N")) | DA25: =IF(CY25="","",IF(CY25<50%,1,IF(AND(CY25>=50%,CY25<B$10),2,IF(CY25>=B$10,3)))) | DB25: =IF(B25<>"",IFERROR(IF((SUMIF(D$14:CS$14,"CLO3",D25:CS25)/'Grade computation'!I$6)=0,0,(SUMIF(D$14:CS$14,"CLO3",D25:CS25)/'Grade computation'!I$6)),""),"") | DC25: =IF(DB25="","",IF(DB25>=B$10,"Y","N")) | DD25: =IF(DB25="","",IF(DB25<50%,1,IF(AND(DB25>=50%,DB25<B$10),2,IF(DB25>=B$10,3)))) | DE25: =IF(B25<>"",IFERROR(SUMIF(D$14:CS$14,"CLO4",D25:CS25)/'Grade computation'!I$7,""),"") | DF25: =IF(DE25="","",IF(DE25>=B$10,"Y","N")) | DG25: =IF(DE25="","",IF(DE25<50%,1,IF(AND(DE25>=50%,DE25<B$10),2,IF(DE25>=B$10,3)))) | DH25: =IF(B25<>"",IFERROR(IF((SUMIF(D$14:CS$14,"CLO5",D25:CS25)/'Grade computation'!I$8)=0,0,(SUMIF(D$14:CS$14,"CLO5",D25:CS25)/'Grade computation'!I$8)),""),"") | DI25: =IF(DH25="","",IF(DH25>=B$10,"Y","N")) | DJ25: =IF(DH25="","",IF(DH25<50%,1,IF(AND(DH25>=50%,DH25<B$10),2,IF(DH25>=B$10,3)))) | DK25: =IF(B25<>"",IFERROR(IF((SUMIF(D$14:CS$14,"CLO6",D25:CS25)/'Grade computation'!I$9)=0,0,(SUMIF(D$14:CS$14,"CLO6",D25:CS25)/'Grade computation'!I$9)),""),"") | DL25: =IF(DK25="","",IF(DK25>=B$10,"Y","N")) | DM25: =IF(DK25="","",IF(DK25<50%,1,IF(AND(DK25>=50%,DK25<B$10),2,IF(DK25>=B$10,3)))) | DN25: =IF(B25<>"",IFERROR(IF((SUMIF(D$14:CS$14,"CLO7",D25:CS25)/'Grade computation'!I$10)=0,0,(SUMIF(D$14:CS$14,"CLO7",D25:CS25)/'Grade computation'!I$10)),""),"") | DO25: =IF(DN25="","",IF(DN25>=B$10,"Y","N")) | DP25: =IF(DN25="","",IF(DN25<50%,1,IF(AND(DN25>=50%,DN25<B$10),2,IF(DN25>=B$10,3)))) | DQ25: =IF(B25<>"",IFERROR(IF((SUMIF(D$14:CS$14,"CLO8",D25:CS25)/'Grade computation'!I$11)=0,0,(SUMIF(D$14:CS$14,"CLO8",D25:CS25)/'Grade computation'!I$11)),""),"") | DR25: =IF(DQ25="","",IF(DQ25>=B$10,"Y","N")) | DS25: =IF(DQ25="","",IF(DQ25<50%,1,IF(AND(DQ25>=50%,DQ25<B$10),2,IF(DQ25>=B$10,3)))) | DT25: =IF(B25<>"",IFERROR(IF((SUMIF(D$14:CS$14,"CLO9",D25:CS25)/'Grade computation'!I$12)=0,0,(SUMIF(D$14:CS$14,"CLO9",D25:CS25)/'Grade computation'!I$12)),""),"") | DU25: =IF(DT25="","",IF(DT25>=B$10,"Y","N")) | DV25: =IF(DT25="","",IF(DT25<50%,1,IF(AND(DT25>=50%,DT25<B$10),2,IF(DT25>=B$10,3)))) | DW25: =IF(B25<>"",IFERROR(IF((SUMIF(D$14:CS$14,"CLO10",D25:CS25)/'Grade computation'!I$13)=0,0,(SUMIF(D$14:CS$14,"CLO10",D25:CS25)/'Grade computation'!I$13)),""),"") | DX25: =IF(DW25="","",IF(DW25>=B$10,"Y","N")) | DY25: =IF(DW25="","",IF(DW25<50%,1,IF(AND(DW25>=50%,DW25<B$10),2,IF(DW25>=B$10,3))))
AH26: =IF(B26<>"",SUMIF(D$12:AG$12,"TLA",D26:AG26),"") | AI26: =IF(B26<>"",SUMIF(D$12:AG$12,"AT",D26:AG26),"") | BN26: =IF(B26<>"", SUMIF(AJ$12:BM$12,"TLA",AJ26:BM26), "") | BO26: =IF(B26<>"", SUMIF(AJ$12:BM$12,"AT",AJ26:BM26), "") | CT26: =IF(B26<>"",SUMIF(BP$12:CS$12,"TLA",BP26:CS26), "") | CU26: =IF(B26<>"",SUMIF(BP$12:CS$12,"AT",BP26:CS26), "") | CV26: =IF(B26<>"",IFERROR(SUMIF(D$14:CS$14, "CLO1", D26:CS26)/'Grade computation'!I$4,""),"") | CW26: =IF(CV26="","",IF(CV26>=B$10,"Y","N")) | CX26: =IF(CV26="","",IF(CV26<50%,1,IF(AND(CV26>=50%,CV26<B$10),2,IF(CV26>=B$10,3)))) | CY26: =IF(B26<>"",IFERROR(IF((SUMIF(D$14:CS$14,"CLO2",D26:CS26)/'Grade computation'!I$5)=0,0,(SUMIF(D$14:CS$14,"CLO2",D26:CS26)/'Grade computation'!I$5)),""),"") | CZ26: =IF(CY26="","",IF(CY26>=B$10,"Y","N")) | DA26: =IF(CY26="","",IF(CY26<50%,1,IF(AND(CY26>=50%,CY26<B$10),2,IF(CY26>=B$10,3)))) | DB26: =IF(B26<>"",IFERROR(IF((SUMIF(D$14:CS$14,"CLO3",D26:CS26)/'Grade computation'!I$6)=0,0,(SUMIF(D$14:CS$14,"CLO3",D26:CS26)/'Grade computation'!I$6)),""),"") | DC26: =IF(DB26="","",IF(DB26>=B$10,"Y","N")) | DD26: =IF(DB26="","",IF(DB26<50%,1,IF(AND(DB26>=50%,DB26<B$10),2,IF(DB26>=B$10,3)))) | DE26: =IF(B26<>"",IFERROR(SUMIF(D$14:CS$14,"CLO4",D26:CS26)/'Grade computation'!I$7,""),"") | DF26: =IF(DE26="","",IF(DE26>=B$10,"Y","N")) | DG26: =IF(DE26="","",IF(DE26<50%,1,IF(AND(DE26>=50%,DE26<B$10),2,IF(DE26>=B$10,3)))) | DH26: =IF(B26<>"",IFERROR(IF((SUMIF(D$14:CS$14,"CLO5",D26:CS26)/'Grade computation'!I$8)=0,0,(SUMIF(D$14:CS$14,"CLO5",D26:CS26)/'Grade computation'!I$8)),""),"") | DI26: =IF(DH26="","",IF(DH26>=B$10,"Y","N")) | DJ26: =IF(DH26="","",IF(DH26<50%,1,IF(AND(DH26>=50%,DH26<B$10),2,IF(DH26>=B$10,3)))) | DK26: =IF(B26<>"",IFERROR(IF((SUMIF(D$14:CS$14,"CLO6",D26:CS26)/'Grade computation'!I$9)=0,0,(SUMIF(D$14:CS$14,"CLO6",D26:CS26)/'Grade computation'!I$9)),""),"") | DL26: =IF(DK26="","",IF(DK26>=B$10,"Y","N")) | DM26: =IF(DK26="","",IF(DK26<50%,1,IF(AND(DK26>=50%,DK26<B$10),2,IF(DK26>=B$10,3)))) | DN26: =IF(B26<>"",IFERROR(IF((SUMIF(D$14:CS$14,"CLO7",D26:CS26)/'Grade computation'!I$10)=0,0,(SUMIF(D$14:CS$14,"CLO7",D26:CS26)/'Grade computation'!I$10)),""),"") | DO26: =IF(DN26="","",IF(DN26>=B$10,"Y","N")) | DP26: =IF(DN26="","",IF(DN26<50%,1,IF(AND(DN26>=50%,DN26<B$10),2,IF(DN26>=B$10,3)))) | DQ26: =IF(B26<>"",IFERROR(IF((SUMIF(D$14:CS$14,"CLO8",D26:CS26)/'Grade computation'!I$11)=0,0,(SUMIF(D$14:CS$14,"CLO8",D26:CS26)/'Grade computation'!I$11)),""),"") | DR26: =IF(DQ26="","",IF(DQ26>=B$10,"Y","N")) | DS26: =IF(DQ26="","",IF(DQ26<50%,1,IF(AND(DQ26>=50%,DQ26<B$10),2,IF(DQ26>=B$10,3)))) | DT26: =IF(B26<>"",IFERROR(IF((SUMIF(D$14:CS$14,"CLO9",D26:CS26)/'Grade computation'!I$12)=0,0,(SUMIF(D$14:CS$14,"CLO9",D26:CS26)/'Grade computation'!I$12)),""),"") | DU26: =IF(DT26="","",IF(DT26>=B$10,"Y","N")) | DV26: =IF(DT26="","",IF(DT26<50%,1,IF(AND(DT26>=50%,DT26<B$10),2,IF(DT26>=B$10,3)))) | DW26: =IF(B26<>"",IFERROR(IF((SUMIF(D$14:CS$14,"CLO10",D26:CS26)/'Grade computation'!I$13)=0,0,(SUMIF(D$14:CS$14,"CLO10",D26:CS26)/'Grade computation'!I$13)),""),"") | DX26: =IF(DW26="","",IF(DW26>=B$10,"Y","N")) | DY26: =IF(DW26="","",IF(DW26<50%,1,IF(AND(DW26>=50%,DW26<B$10),2,IF(DW26>=B$10,3))))
AH27: =IF(B27<>"",SUMIF(D$12:AG$12,"TLA",D27:AG27),"") | AI27: =IF(B27<>"",SUMIF(D$12:AG$12,"AT",D27:AG27),"") | BN27: =IF(B27<>"", SUMIF(AJ$12:BM$12,"TLA",AJ27:BM27), "") | BO27: =IF(B27<>"", SUMIF(AJ$12:BM$12,"AT",AJ27:BM27), "") | CT27: =IF(B27<>"",SUMIF(BP$12:CS$12,"TLA",BP27:CS27), "") | CU27: =IF(B27<>"",SUMIF(BP$12:CS$12,"AT",BP27:CS27), "") | CV27: =IF(B27<>"",IFERROR(SUMIF(D$14:CS$14, "CLO1", D27:CS27)/'Grade computation'!I$4,""),"") | CW27: =IF(CV27="","",IF(CV27>=B$10,"Y","N")) | CX27: =IF(CV27="","",IF(CV27<50%,1,IF(AND(CV27>=50%,CV27<B$10),2,IF(CV27>=B$10,3)))) | CY27: =IF(B27<>"",IFERROR(IF((SUMIF(D$14:CS$14,"CLO2",D27:CS27)/'Grade computation'!I$5)=0,0,(SUMIF(D$14:CS$14,"CLO2",D27:CS27)/'Grade computation'!I$5)),""),"") | CZ27: =IF(CY27="","",IF(CY27>=B$10,"Y","N")) | DA27: =IF(CY27="","",IF(CY27<50%,1,IF(AND(CY27>=50%,CY27<B$10),2,IF(CY27>=B$10,3)))) | DB27: =IF(B27<>"",IFERROR(IF((SUMIF(D$14:CS$14,"CLO3",D27:CS27)/'Grade computation'!I$6)=0,0,(SUMIF(D$14:CS$14,"CLO3",D27:CS27)/'Grade computation'!I$6)),""),"") | DC27: =IF(DB27="","",IF(DB27>=B$10,"Y","N")) | DD27: =IF(DB27="","",IF(DB27<50%,1,IF(AND(DB27>=50%,DB27<B$10),2,IF(DB27>=B$10,3)))) | DE27: =IF(B27<>"",IFERROR(SUMIF(D$14:CS$14,"CLO4",D27:CS27)/'Grade computation'!I$7,""),"") | DF27: =IF(DE27="","",IF(DE27>=B$10,"Y","N")) | DG27: =IF(DE27="","",IF(DE27<50%,1,IF(AND(DE27>=50%,DE27<B$10),2,IF(DE27>=B$10,3)))) | DH27: =IF(B27<>"",IFERROR(IF((SUMIF(D$14:CS$14,"CLO5",D27:CS27)/'Grade computation'!I$8)=0,0,(SUMIF(D$14:CS$14,"CLO5",D27:CS27)/'Grade computation'!I$8)),""),"") | DI27: =IF(DH27="","",IF(DH27>=B$10,"Y","N")) | DJ27: =IF(DH27="","",IF(DH27<50%,1,IF(AND(DH27>=50%,DH27<B$10),2,IF(DH27>=B$10,3)))) | DK27: =IF(B27<>"",IFERROR(IF((SUMIF(D$14:CS$14,"CLO6",D27:CS27)/'Grade computation'!I$9)=0,0,(SUMIF(D$14:CS$14,"CLO6",D27:CS27)/'Grade computation'!I$9)),""),"") | DL27: =IF(DK27="","",IF(DK27>=B$10,"Y","N")) | DM27: =IF(DK27="","",IF(DK27<50%,1,IF(AND(DK27>=50%,DK27<B$10),2,IF(DK27>=B$10,3)))) | DN27: =IF(B27<>"",IFERROR(IF((SUMIF(D$14:CS$14,"CLO7",D27:CS27)/'Grade computation'!I$10)=0,0,(SUMIF(D$14:CS$14,"CLO7",D27:CS27)/'Grade computation'!I$10)),""),"") | DO27: =IF(DN27="","",IF(DN27>=B$10,"Y","N")) | DP27: =IF(DN27="","",IF(DN27<50%,1,IF(AND(DN27>=50%,DN27<B$10),2,IF(DN27>=B$10,3)))) | DQ27: =IF(B27<>"",IFERROR(IF((SUMIF(D$14:CS$14,"CLO8",D27:CS27)/'Grade computation'!I$11)=0,0,(SUMIF(D$14:CS$14,"CLO8",D27:CS27)/'Grade computation'!I$11)),""),"") | DR27: =IF(DQ27="","",IF(DQ27>=B$10,"Y","N")) | DS27: =IF(DQ27="","",IF(DQ27<50%,1,IF(AND(DQ27>=50%,DQ27<B$10),2,IF(DQ27>=B$10,3)))) | DT27: =IF(B27<>"",IFERROR(IF((SUMIF(D$14:CS$14,"CLO9",D27:CS27)/'Grade computation'!I$12)=0,0,(SUMIF(D$14:CS$14,"CLO9",D27:CS27)/'Grade computation'!I$12)),""),"") | DU27: =IF(DT27="","",IF(DT27>=B$10,"Y","N")) | DV27: =IF(DT27="","",IF(DT27<50%,1,IF(AND(DT27>=50%,DT27<B$10),2,IF(DT27>=B$10,3)))) | DW27: =IF(B27<>"",IFERROR(IF((SUMIF(D$14:CS$14,"CLO10",D27:CS27)/'Grade computation'!I$13)=0,0,(SUMIF(D$14:CS$14,"CLO10",D27:CS27)/'Grade computation'!I$13)),""),"") | DX27: =IF(DW27="","",IF(DW27>=B$10,"Y","N")) | DY27: =IF(DW27="","",IF(DW27<50%,1,IF(AND(DW27>=50%,DW27<B$10),2,IF(DW27>=B$10,3))))
AH28: =IF(B28<>"",SUMIF(D$12:AG$12,"TLA",D28:AG28),"") | AI28: =IF(B28<>"",SUMIF(D$12:AG$12,"AT",D28:AG28),"") | BN28: =IF(B28<>"", SUMIF(AJ$12:BM$12,"TLA",AJ28:BM28), "") | BO28: =IF(B28<>"", SUMIF(AJ$12:BM$12,"AT",AJ28:BM28), "") | CT28: =IF(B28<>"",SUMIF(BP$12:CS$12,"TLA",BP28:CS28), "") | CU28: =IF(B28<>"",SUMIF(BP$12:CS$12,"AT",BP28:CS28), "") | CV28: =IF(B28<>"",IFERROR(SUMIF(D$14:CS$14, "CLO1", D28:CS28)/'Grade computation'!I$4,""),"") | CW28: =IF(CV28="","",IF(CV28>=B$10,"Y","N")) | CX28: =IF(CV28="","",IF(CV28<50%,1,IF(AND(CV28>=50%,CV28<B$10),2,IF(CV28>=B$10,3)))) | CY28: =IF(B28<>"",IFERROR(IF((SUMIF(D$14:CS$14,"CLO2",D28:CS28)/'Grade computation'!I$5)=0,0,(SUMIF(D$14:CS$14,"CLO2",D28:CS28)/'Grade computation'!I$5)),""),"") | CZ28: =IF(CY28="","",IF(CY28>=B$10,"Y","N")) | DA28: =IF(CY28="","",IF(CY28<50%,1,IF(AND(CY28>=50%,CY28<B$10),2,IF(CY28>=B$10,3)))) | DB28: =IF(B28<>"",IFERROR(IF((SUMIF(D$14:CS$14,"CLO3",D28:CS28)/'Grade computation'!I$6)=0,0,(SUMIF(D$14:CS$14,"CLO3",D28:CS28)/'Grade computation'!I$6)),""),"") | DC28: =IF(DB28="","",IF(DB28>=B$10,"Y","N")) | DD28: =IF(DB28="","",IF(DB28<50%,1,IF(AND(DB28>=50%,DB28<B$10),2,IF(DB28>=B$10,3)))) | DE28: =IF(B28<>"",IFERROR(SUMIF(D$14:CS$14,"CLO4",D28:CS28)/'Grade computation'!I$7,""),"") | DF28: =IF(DE28="","",IF(DE28>=B$10,"Y","N")) | DG28: =IF(DE28="","",IF(DE28<50%,1,IF(AND(DE28>=50%,DE28<B$10),2,IF(DE28>=B$10,3)))) | DH28: =IF(B28<>"",IFERROR(IF((SUMIF(D$14:CS$14,"CLO5",D28:CS28)/'Grade computation'!I$8)=0,0,(SUMIF(D$14:CS$14,"CLO5",D28:CS28)/'Grade computation'!I$8)),""),"") | DI28: =IF(DH28="","",IF(DH28>=B$10,"Y","N")) | DJ28: =IF(DH28="","",IF(DH28<50%,1,IF(AND(DH28>=50%,DH28<B$10),2,IF(DH28>=B$10,3)))) | DK28: =IF(B28<>"",IFERROR(IF((SUMIF(D$14:CS$14,"CLO6",D28:CS28)/'Grade computation'!I$9)=0,0,(SUMIF(D$14:CS$14,"CLO6",D28:CS28)/'Grade computation'!I$9)),""),"") | DL28: =IF(DK28="","",IF(DK28>=B$10,"Y","N")) | DM28: =IF(DK28="","",IF(DK28<50%,1,IF(AND(DK28>=50%,DK28<B$10),2,IF(DK28>=B$10,3)))) | DN28: =IF(B28<>"",IFERROR(IF((SUMIF(D$14:CS$14,"CLO7",D28:CS28)/'Grade computation'!I$10)=0,0,(SUMIF(D$14:CS$14,"CLO7",D28:CS28)/'Grade computation'!I$10)),""),"") | DO28: =IF(DN28="","",IF(DN28>=B$10,"Y","N")) | DP28: =IF(DN28="","",IF(DN28<50%,1,IF(AND(DN28>=50%,DN28<B$10),2,IF(DN28>=B$10,3)))) | DQ28: =IF(B28<>"",IFERROR(IF((SUMIF(D$14:CS$14,"CLO8",D28:CS28)/'Grade computation'!I$11)=0,0,(SUMIF(D$14:CS$14,"CLO8",D28:CS28)/'Grade computation'!I$11)),""),"") | DR28: =IF(DQ28="","",IF(DQ28>=B$10,"Y","N")) | DS28: =IF(DQ28="","",IF(DQ28<50%,1,IF(AND(DQ28>=50%,DQ28<B$10),2,IF(DQ28>=B$10,3)))) | DT28: =IF(B28<>"",IFERROR(IF((SUMIF(D$14:CS$14,"CLO9",D28:CS28)/'Grade computation'!I$12)=0,0,(SUMIF(D$14:CS$14,"CLO9",D28:CS28)/'Grade computation'!I$12)),""),"") | DU28: =IF(DT28="","",IF(DT28>=B$10,"Y","N")) | DV28: =IF(DT28="","",IF(DT28<50%,1,IF(AND(DT28>=50%,DT28<B$10),2,IF(DT28>=B$10,3)))) | DW28: =IF(B28<>"",IFERROR(IF((SUMIF(D$14:CS$14,"CLO10",D28:CS28)/'Grade computation'!I$13)=0,0,(SUMIF(D$14:CS$14,"CLO10",D28:CS28)/'Grade computation'!I$13)),""),"") | DX28: =IF(DW28="","",IF(DW28>=B$10,"Y","N")) | DY28: =IF(DW28="","",IF(DW28<50%,1,IF(AND(DW28>=50%,DW28<B$10),2,IF(DW28>=B$10,3))))
AH29: =IF(B29<>"",SUMIF(D$12:AG$12,"TLA",D29:AG29),"") | AI29: =IF(B29<>"",SUMIF(D$12:AG$12,"AT",D29:AG29),"") | BN29: =IF(B29<>"", SUMIF(AJ$12:BM$12,"TLA",AJ29:BM29), "") | BO29: =IF(B29<>"", SUMIF(AJ$12:BM$12,"AT",AJ29:BM29), "") | CT29: =IF(B29<>"",SUMIF(BP$12:CS$12,"TLA",BP29:CS29), "") | CU29: =IF(B29<>"",SUMIF(BP$12:CS$12,"AT",BP29:CS29), "") | CV29: =IF(B29<>"",IFERROR(SUMIF(D$14:CS$14, "CLO1", D29:CS29)/'Grade computation'!I$4,""),"") | CW29: =IF(CV29="","",IF(CV29>=B$10,"Y","N")) | CX29: =IF(CV29="","",IF(CV29<50%,1,IF(AND(CV29>=50%,CV29<B$10),2,IF(CV29>=B$10,3)))) | CY29: =IF(B29<>"",IFERROR(IF((SUMIF(D$14:CS$14,"CLO2",D29:CS29)/'Grade computation'!I$5)=0,0,(SUMIF(D$14:CS$14,"CLO2",D29:CS29)/'Grade computation'!I$5)),""),"") | CZ29: =IF(CY29="","",IF(CY29>=B$10,"Y","N")) | DA29: =IF(CY29="","",IF(CY29<50%,1,IF(AND(CY29>=50%,CY29<B$10),2,IF(CY29>=B$10,3)))) | DB29: =IF(B29<>"",IFERROR(IF((SUMIF(D$14:CS$14,"CLO3",D29:CS29)/'Grade computation'!I$6)=0,0,(SUMIF(D$14:CS$14,"CLO3",D29:CS29)/'Grade computation'!I$6)),""),"") | DC29: =IF(DB29="","",IF(DB29>=B$10,"Y","N")) | DD29: =IF(DB29="","",IF(DB29<50%,1,IF(AND(DB29>=50%,DB29<B$10),2,IF(DB29>=B$10,3)))) | DE29: =IF(B29<>"",IFERROR(SUMIF(D$14:CS$14,"CLO4",D29:CS29)/'Grade computation'!I$7,""),"") | DF29: =IF(DE29="","",IF(DE29>=B$10,"Y","N")) | DG29: =IF(DE29="","",IF(DE29<50%,1,IF(AND(DE29>=50%,DE29<B$10),2,IF(DE29>=B$10,3)))) | DH29: =IF(B29<>"",IFERROR(IF((SUMIF(D$14:CS$14,"CLO5",D29:CS29)/'Grade computation'!I$8)=0,0,(SUMIF(D$14:CS$14,"CLO5",D29:CS29)/'Grade computation'!I$8)),""),"") | DI29: =IF(DH29="","",IF(DH29>=B$10,"Y","N")) | DJ29: =IF(DH29="","",IF(DH29<50%,1,IF(AND(DH29>=50%,DH29<B$10),2,IF(DH29>=B$10,3)))) | DK29: =IF(B29<>"",IFERROR(IF((SUMIF(D$14:CS$14,"CLO6",D29:CS29)/'Grade computation'!I$9)=0,0,(SUMIF(D$14:CS$14,"CLO6",D29:CS29)/'Grade computation'!I$9)),""),"") | DL29: =IF(DK29="","",IF(DK29>=B$10,"Y","N")) | DM29: =IF(DK29="","",IF(DK29<50%,1,IF(AND(DK29>=50%,DK29<B$10),2,IF(DK29>=B$10,3)))) | DN29: =IF(B29<>"",IFERROR(IF((SUMIF(D$14:CS$14,"CLO7",D29:CS29)/'Grade computation'!I$10)=0,0,(SUMIF(D$14:CS$14,"CLO7",D29:CS29)/'Grade computation'!I$10)),""),"") | DO29: =IF(DN29="","",IF(DN29>=B$10,"Y","N")) | DP29: =IF(DN29="","",IF(DN29<50%,1,IF(AND(DN29>=50%,DN29<B$10),2,IF(DN29>=B$10,3)))) | DQ29: =IF(B29<>"",IFERROR(IF((SUMIF(D$14:CS$14,"CLO8",D29:CS29)/'Grade computation'!I$11)=0,0,(SUMIF(D$14:CS$14,"CLO8",D29:CS29)/'Grade computation'!I$11)),""),"") | DR29: =IF(DQ29="","",IF(DQ29>=B$10,"Y","N")) | DS29: =IF(DQ29="","",IF(DQ29<50%,1,IF(AND(DQ29>=50%,DQ29<B$10),2,IF(DQ29>=B$10,3)))) | DT29: =IF(B29<>"",IFERROR(IF((SUMIF(D$14:CS$14,"CLO9",D29:CS29)/'Grade computation'!I$12)=0,0,(SUMIF(D$14:CS$14,"CLO9",D29:CS29)/'Grade computation'!I$12)),""),"") | DU29: =IF(DT29="","",IF(DT29>=B$10,"Y","N")) | DV29: =IF(DT29="","",IF(DT29<50%,1,IF(AND(DT29>=50%,DT29<B$10),2,IF(DT29>=B$10,3)))) | DW29: =IF(B29<>"",IFERROR(IF((SUMIF(D$14:CS$14,"CLO10",D29:CS29)/'Grade computation'!I$13)=0,0,(SUMIF(D$14:CS$14,"CLO10",D29:CS29)/'Grade computation'!I$13)),""),"") | DX29: =IF(DW29="","",IF(DW29>=B$10,"Y","N")) | DY29: =IF(DW29="","",IF(DW29<50%,1,IF(AND(DW29>=50%,DW29<B$10),2,IF(DW29>=B$10,3))))
AH30: =IF(B30<>"",SUMIF(D$12:AG$12,"TLA",D30:AG30),"") | AI30: =IF(B30<>"",SUMIF(D$12:AG$12,"AT",D30:AG30),"") | BN30: =IF(B30<>"", SUMIF(AJ$12:BM$12,"TLA",AJ30:BM30), "") | BO30: =IF(B30<>"", SUMIF(AJ$12:BM$12,"AT",AJ30:BM30), "") | CT30: =IF(B30<>"",SUMIF(BP$12:CS$12,"TLA",BP30:CS30), "") | CU30: =IF(B30<>"",SUMIF(BP$12:CS$12,"AT",BP30:CS30), "") | CV30: =IF(B30<>"",IFERROR(SUMIF(D$14:CS$14, "CLO1", D30:CS30)/'Grade computation'!I$4,""),"") | CW30: =IF(CV30="","",IF(CV30>=B$10,"Y","N")) | CX30: =IF(CV30="","",IF(CV30<50%,1,IF(AND(CV30>=50%,CV30<B$10),2,IF(CV30>=B$10,3)))) | CY30: =IF(B30<>"",IFERROR(IF((SUMIF(D$14:CS$14,"CLO2",D30:CS30)/'Grade computation'!I$5)=0,0,(SUMIF(D$14:CS$14,"CLO2",D30:CS30)/'Grade computation'!I$5)),""),"") | CZ30: =IF(CY30="","",IF(CY30>=B$10,"Y","N")) | DA30: =IF(CY30="","",IF(CY30<50%,1,IF(AND(CY30>=50%,CY30<B$10),2,IF(CY30>=B$10,3)))) | DB30: =IF(B30<>"",IFERROR(IF((SUMIF(D$14:CS$14,"CLO3",D30:CS30)/'Grade computation'!I$6)=0,0,(SUMIF(D$14:CS$14,"CLO3",D30:CS30)/'Grade computation'!I$6)),""),"") | DC30: =IF(DB30="","",IF(DB30>=B$10,"Y","N")) | DD30: =IF(DB30="","",IF(DB30<50%,1,IF(AND(DB30>=50%,DB30<B$10),2,IF(DB30>=B$10,3)))) | DE30: =IF(B30<>"",IFERROR(SUMIF(D$14:CS$14,"CLO4",D30:CS30)/'Grade computation'!I$7,""),"") | DF30: =IF(DE30="","",IF(DE30>=B$10,"Y","N")) | DG30: =IF(DE30="","",IF(DE30<50%,1,IF(AND(DE30>=50%,DE30<B$10),2,IF(DE30>=B$10,3)))) | DH30: =IF(B30<>"",IFERROR(IF((SUMIF(D$14:CS$14,"CLO5",D30:CS30)/'Grade computation'!I$8)=0,0,(SUMIF(D$14:CS$14,"CLO5",D30:CS30)/'Grade computation'!I$8)),""),"") | DI30: =IF(DH30="","",IF(DH30>=B$10,"Y","N")) | DJ30: =IF(DH30="","",IF(DH30<50%,1,IF(AND(DH30>=50%,DH30<B$10),2,IF(DH30>=B$10,3)))) | DK30: =IF(B30<>"",IFERROR(IF((SUMIF(D$14:CS$14,"CLO6",D30:CS30)/'Grade computation'!I$9)=0,0,(SUMIF(D$14:CS$14,"CLO6",D30:CS30)/'Grade computation'!I$9)),""),"") | DL30: =IF(DK30="","",IF(DK30>=B$10,"Y","N")) | DM30: =IF(DK30="","",IF(DK30<50%,1,IF(AND(DK30>=50%,DK30<B$10),2,IF(DK30>=B$10,3)))) | DN30: =IF(B30<>"",IFERROR(IF((SUMIF(D$14:CS$14,"CLO7",D30:CS30)/'Grade computation'!I$10)=0,0,(SUMIF(D$14:CS$14,"CLO7",D30:CS30)/'Grade computation'!I$10)),""),"") | DO30: =IF(DN30="","",IF(DN30>=B$10,"Y","N")) | DP30: =IF(DN30="","",IF(DN30<50%,1,IF(AND(DN30>=50%,DN30<B$10),2,IF(DN30>=B$10,3)))) | DQ30: =IF(B30<>"",IFERROR(IF((SUMIF(D$14:CS$14,"CLO8",D30:CS30)/'Grade computation'!I$11)=0,0,(SUMIF(D$14:CS$14,"CLO8",D30:CS30)/'Grade computation'!I$11)),""),"") | DR30: =IF(DQ30="","",IF(DQ30>=B$10,"Y","N")) | DS30: =IF(DQ30="","",IF(DQ30<50%,1,IF(AND(DQ30>=50%,DQ30<B$10),2,IF(DQ30>=B$10,3)))) | DT30: =IF(B30<>"",IFERROR(IF((SUMIF(D$14:CS$14,"CLO9",D30:CS30)/'Grade computation'!I$12)=0,0,(SUMIF(D$14:CS$14,"CLO9",D30:CS30)/'Grade computation'!I$12)),""),"") | DU30: =IF(DT30="","",IF(DT30>=B$10,"Y","N")) | DV30: =IF(DT30="","",IF(DT30<50%,1,IF(AND(DT30>=50%,DT30<B$10),2,IF(DT30>=B$10,3)))) | DW30: =IF(B30<>"",IFERROR(IF((SUMIF(D$14:CS$14,"CLO10",D30:CS30)/'Grade computation'!I$13)=0,0,(SUMIF(D$14:CS$14,"CLO10",D30:CS30)/'Grade computation'!I$13)),""),"") | DX30: =IF(DW30="","",IF(DW30>=B$10,"Y","N")) | DY30: =IF(DW30="","",IF(DW30<50%,1,IF(AND(DW30>=50%,DW30<B$10),2,IF(DW30>=B$10,3))))
AH31: =IF(B31<>"",SUMIF(D$12:AG$12,"TLA",D31:AG31),"") | AI31: =IF(B31<>"",SUMIF(D$12:AG$12,"AT",D31:AG31),"") | BN31: =IF(B31<>"", SUMIF(AJ$12:BM$12,"TLA",AJ31:BM31), "") | BO31: =IF(B31<>"", SUMIF(AJ$12:BM$12,"AT",AJ31:BM31), "") | CT31: =IF(B31<>"",SUMIF(BP$12:CS$12,"TLA",BP31:CS31), "") | CU31: =IF(B31<>"",SUMIF(BP$12:CS$12,"AT",BP31:CS31), "") | CV31: =IF(B31<>"",IFERROR(SUMIF(D$14:CS$14, "CLO1", D31:CS31)/'Grade computation'!I$4,""),"") | CW31: =IF(CV31="","",IF(CV31>=B$10,"Y","N")) | CX31: =IF(CV31="","",IF(CV31<50%,1,IF(AND(CV31>=50%,CV31<B$10),2,IF(CV31>=B$10,3)))) | CY31: =IF(B31<>"",IFERROR(IF((SUMIF(D$14:CS$14,"CLO2",D31:CS31)/'Grade computation'!I$5)=0,0,(SUMIF(D$14:CS$14,"CLO2",D31:CS31)/'Grade computation'!I$5)),""),"") | CZ31: =IF(CY31="","",IF(CY31>=B$10,"Y","N")) | DA31: =IF(CY31="","",IF(CY31<50%,1,IF(AND(CY31>=50%,CY31<B$10),2,IF(CY31>=B$10,3)))) | DB31: =IF(B31<>"",IFERROR(IF((SUMIF(D$14:CS$14,"CLO3",D31:CS31)/'Grade computation'!I$6)=0,0,(SUMIF(D$14:CS$14,"CLO3",D31:CS31)/'Grade computation'!I$6)),""),"") | DC31: =IF(DB31="","",IF(DB31>=B$10,"Y","N")) | DD31: =IF(DB31="","",IF(DB31<50%,1,IF(AND(DB31>=50%,DB31<B$10),2,IF(DB31>=B$10,3)))) | DE31: =IF(B31<>"",IFERROR(SUMIF(D$14:CS$14,"CLO4",D31:CS31)/'Grade computation'!I$7,""),"") | DF31: =IF(DE31="","",IF(DE31>=B$10,"Y","N")) | DG31: =IF(DE31="","",IF(DE31<50%,1,IF(AND(DE31>=50%,DE31<B$10),2,IF(DE31>=B$10,3)))) | DH31: =IF(B31<>"",IFERROR(IF((SUMIF(D$14:CS$14,"CLO5",D31:CS31)/'Grade computation'!I$8)=0,0,(SUMIF(D$14:CS$14,"CLO5",D31:CS31)/'Grade computation'!I$8)),""),"") | DI31: =IF(DH31="","",IF(DH31>=B$10,"Y","N")) | DJ31: =IF(DH31="","",IF(DH31<50%,1,IF(AND(DH31>=50%,DH31<B$10),2,IF(DH31>=B$10,3)))) | DK31: =IF(B31<>"",IFERROR(IF((SUMIF(D$14:CS$14,"CLO6",D31:CS31)/'Grade computation'!I$9)=0,0,(SUMIF(D$14:CS$14,"CLO6",D31:CS31)/'Grade computation'!I$9)),""),"") | DL31: =IF(DK31="","",IF(DK31>=B$10,"Y","N")) | DM31: =IF(DK31="","",IF(DK31<50%,1,IF(AND(DK31>=50%,DK31<B$10),2,IF(DK31>=B$10,3)))) | DN31: =IF(B31<>"",IFERROR(IF((SUMIF(D$14:CS$14,"CLO7",D31:CS31)/'Grade computation'!I$10)=0,0,(SUMIF(D$14:CS$14,"CLO7",D31:CS31)/'Grade computation'!I$10)),""),"") | DO31: =IF(DN31="","",IF(DN31>=B$10,"Y","N")) | DP31: =IF(DN31="","",IF(DN31<50%,1,IF(AND(DN31>=50%,DN31<B$10),2,IF(DN31>=B$10,3)))) | DQ31: =IF(B31<>"",IFERROR(IF((SUMIF(D$14:CS$14,"CLO8",D31:CS31)/'Grade computation'!I$11)=0,0,(SUMIF(D$14:CS$14,"CLO8",D31:CS31)/'Grade computation'!I$11)),""),"") | DR31: =IF(DQ31="","",IF(DQ31>=B$10,"Y","N")) | DS31: =IF(DQ31="","",IF(DQ31<50%,1,IF(AND(DQ31>=50%,DQ31<B$10),2,IF(DQ31>=B$10,3)))) | DT31: =IF(B31<>"",IFERROR(IF((SUMIF(D$14:CS$14,"CLO9",D31:CS31)/'Grade computation'!I$12)=0,0,(SUMIF(D$14:CS$14,"CLO9",D31:CS31)/'Grade computation'!I$12)),""),"") | DU31: =IF(DT31="","",IF(DT31>=B$10,"Y","N")) | DV31: =IF(DT31="","",IF(DT31<50%,1,IF(AND(DT31>=50%,DT31<B$10),2,IF(DT31>=B$10,3)))) | DW31: =IF(B31<>"",IFERROR(IF((SUMIF(D$14:CS$14,"CLO10",D31:CS31)/'Grade computation'!I$13)=0,0,(SUMIF(D$14:CS$14,"CLO10",D31:CS31)/'Grade computation'!I$13)),""),"") | DX31: =IF(DW31="","",IF(DW31>=B$10,"Y","N")) | DY31: =IF(DW31="","",IF(DW31<50%,1,IF(AND(DW31>=50%,DW31<B$10),2,IF(DW31>=B$10,3))))
